Workbook

Sheet AREAS
O1: Empreendimentos | P1: Cidades | Q1: UF | R1: Unidades Lotes | S1: Área Total | T1: Hectare | U1: VGV Total | V1: VGV BT
O2: =SUBTOTAL(103,N4:N185) -> 182 | P2: =COUNTA(_xlfn.UNIQUE(L4:L189)) -> 70 | Q2: =COUNTA(_xlfn.UNIQUE(M4:M312)) -> 18 | R2: =SUM(AJ4:AJ295) -> 213609.38 | S2: =SUM(AC4:AC164) -> 38796401 | T2: =S2/10000 -> 3879.6401 | U2: =SUM(AL4:AL164) -> 25412.967 | V2: =SUM(AM4:AM164) -> 17037.866
A3: ID | B3: Nome | C3: Links | D3: [ON / OFF] | E3: Status da área | F3: # UAU LAND-BANK | G3: # Workflow | H3: Empresa UAU | I3: Obra UAU | J3: Código Modelo | K3: Regional | L3: Cidade | M3: UF | N3: Empreendimento | O3: Tipo de Contrato | P3: Valor de Compra da Área - Aquisição (R$mm) | Q3: Tipo | R3: Projeto Feito | S3: Year | T3: Data de Lançamento | U3: Participação Buriti | V3: Participação Terreneiro (não paga obra) | W3: Participação Buriti + Terreneiro | X3: Comisão / Terreneiro | Y3: Adm. E Manutenção / Terreneiro | Z3: Tributos / Terreneiro | AA3: Participação Líquida Terreneiro | AB3: Participação de Sócios Minoritários (paga obra) | AC3: Area Total m2 | AD3: Data de Inicio de Construção | AE3: Custo Total do Terreno (Pré Rateio - R$mm) | AF3: Custo Total do Terreno (% do VGV) | AG3: Custo de Construção (Pré Rateio - R$mm) | AH3: Valor m2 Obra | AI3: m2 por Unidade | AJ3: Total de Unidades | AK3: Valor m2 Venda | AL3: VGV Total (R$mm) | AM3: VGV Total (R$mm) BT | AN3: Valor médio por terreno | AO3: Custo médio por terreno | AP3: % Paga obra | AQ3: Margem | AR3: Situação do Empreendimento
A4: MAP001 | B4: CIDADE JARDIM - ETP I - BELA VISTA | C4: https://earth.google.com/web/search/BELA+VISTA/@-16.96124568,-48.94579579,823.03102905a,3707.10942264d,35y,-0h,0t,0r/data=CnkaSxJFCiUweDkzNWYyNTZjZmU4NDk4OGQ6MHhiNDk0MzE3NTE3MDU3YTA5GVl5E43_-DDAIcOVWL7TeUjAKgpCRUxBIFZJU1RBGAIgASImCiQJ0WMLs4K1IMAREBK2sOjBIMAZM_Z2zLqhSMAh4pu9YBioSMBCAggBOgMKATBCAggASggIl-fxrwUQAA?authuser=0 | D4: 1 | E4: LandBank | G4: 2040 | J4: 355 | K4: CENTRO-OESTE I | L4: BELA VISTA DE GOIÁS | M4: GO | N4: CIDADE JARDIM - ETP I | O4: Arrematação judicial | P4: 11775750 | Q4: Loteamento | R4: Sim | S4: 2026 | T4: 46203 | U4: 0.75 | V4: 0.25 | W4: =SUM(U4:V4) -> 1 | X4: 0.05 | Y4: 0.09 | Z4: 0.068 | AA4: 0.198 | AC4: =AI4*AJ4 -> 265341.3 | AE4: =P4/10^6 -> 11.77575 | AF4: =IF(AL4=0,0,AE4/AL4) -> 0.090570683 | AG4: =(AH4*AI4*AJ4)/10^6 -> 39.270512 | AH4: 148 | AI4: 304.99 | AJ4: 870 | AK4: 490 | AL4: =(AK4*AJ4*AI4)/10^6 -> 130.01724 | AM4: =AL4*U4 -> 97.512928 | AN4: =AI4*AK4 -> 149445.1 | AO4: =AH4*AI4 -> 45138.52 | AP4: =U4+AB4 -> 0.75 | AQ4: =AL4*AP4/(AG4+AE4) -> 1.9102854 | AR4: A lançar
A5: MAP122 | B5: JARDIM DO CERRADO 7 - GOIÂNIA | C5: https://earth.google.com/web/search/GOI%c3%82NIA/@-16.67746594,-49.42770992,858.01737984a,4789.30417081d,35y,9.31126662h,0.18897674t,360r/data=CiwiJgokCTImrsNH8yrAEajobj-t-irAGWOHbhWxkEjAIXn8jCOOlEjAQgIIAToDCgEwQgIIAEoICJfn8a8FEAA?authuser=0 | D5: 1 | E5: LandBank | G5: 2770 | J5: 360 | K5: CENTRO-OESTE II | L5: GOIÂNIA | M5: GO | N5: JARDIM DO CERRADO 7 | O5: Parceria | P5: 0 | Q5: Loteamento | R5: - | S5: 2026 | T5: 46295 | U5: 0.8 | W5: =SUM(U5:V5) -> 0.8 | AA5: 0.198 | AB5: 0.2 | AC5: =AI5*AJ5 -> 192245.77 | AE5: =P5/10^6 -> 0 | AF5: =IF(AL5=0,0,AE5/AL5) -> 0 | AG5: =(AH5*AI5*AJ5)/10^6 -> 28.452374 | AH5: 148 | AI5: 384.49154 | AJ5: 500 | AK5: 500 | AL5: =(AK5*AJ5*AI5)/10^6 -> 96.122886 | AM5: =AL5*U5 -> 76.898309 | AN5: =AI5*AK5 -> 192245.77 | AO5: =AH5*AI5 -> 56904.748 | AP5: =U5+AB5 -> 1 | AQ5: =AL5*AP5/(AG5+AE5) -> 3.3783784 | AR5: A lançar
A6: MAP122 | B6: JARDIM DO CERRADO 8 - GOIÂNIA | C6: https://earth.google.com/web/search/GOI%c3%82NIA/@-16.67746594,-49.42770992,858.01737984a,4789.30417081d,35y,9.31126662h,0.18897674t,360r/data=CiwiJgokCTImrsNH8yrAEajobj-t-irAGWOHbhWxkEjAIXn8jCOOlEjAQgIIAToDCgEwQgIIAEoICJfn8a8FEAA?authuser=0 | D6: 1 | E6: LandBank | G6: 2770 | J6: 361 | K6: CENTRO-OESTE II | L6: GOIÂNIA | M6: GO | N6: JARDIM DO CERRADO 8 | O6: Parceria | P6: 0 | Q6: Loteamento | R6: - | S6: 2026 | T6: 46295 | U6: 0.8 | W6: =SUM(U6:V6) -> 0.8 | AA6: 0.198 | AB6: 0.2 | AC6: =AI6*AJ6 -> 139944.68 | AE6: =P6/10^6 -> 0 | AF6: =IF(AL6=0,0,AE6/AL6) -> 0 | AG6: =(AH6*AI6*AJ6)/10^6 -> 20.711813 | AH6: 148 | AI6: 279.88937 | AJ6: 500 | AK6: 500 | AL6: =(AK6*AJ6*AI6)/10^6 -> 69.972342 | AM6: =AL6*U6 -> 55.977874 | AN6: =AI6*AK6 -> 139944.68 | AO6: =AH6*AI6 -> 41423.627 | AP6: =U6+AB6 -> 1 | AQ6: =AL6*AP6/(AG6+AE6) -> 3.3783784 | AR6: A lançar
A7: MAP122 | B7: JARDIM DO CERRADO 9 - GOIÂNIA | C7: https://earth.google.com/web/search/GOI%c3%82NIA/@-16.67746594,-49.42770992,858.01737984a,4789.30417081d,35y,9.31126662h,0.18897674t,360r/data=CiwiJgokCTImrsNH8yrAEajobj-t-irAGWOHbhWxkEjAIXn8jCOOlEjAQgIIAToDCgEwQgIIAEoICJfn8a8FEAA?authuser=0 | D7: 1 | E7: LandBank | G7: 2770 | J7: 363 | K7: CENTRO-OESTE II | L7: GOIÂNIA | M7: GO | N7: JARDIM DO CERRADO 9 | O7: Parceria | P7: 0 | Q7: Loteamento | R7: - | S7: 2026 | T7: 46387 | U7: 0.8 | W7: =SUM(U7:V7) -> 0.8 | AA7: 0.198 | AB7: 0.2 | AC7: =AI7*AJ7 -> 141436.02 | AE7: =P7/10^6 -> 0 | AF7: =IF(AL7=0,0,AE7/AL7) -> 0 | AG7: =(AH7*AI7*AJ7)/10^6 -> 20.932531 | AH7: 148 | AI7: 282.87205 | AJ7: 500 | AK7: 500 | AL7: =(AK7*AJ7*AI7)/10^6 -> 70.718012 | AM7: =AL7*U7 -> 56.574409 | AN7: =AI7*AK7 -> 141436.02 | AO7: =AH7*AI7 -> 41865.063 | AP7: =U7+AB7 -> 1 | AQ7: =AL7*AP7/(AG7+AE7) -> 3.3783784 | AR7: A lançar
A8: MAP033 | B8: BURITI GARDEN PRIME - MARECHAL DEODORO | C8: https://earth.google.com/web/search/MARECHAL+DEODORO/@-9.75268373,-35.84765408,4.2701174a,3214.95034437d,35y,0h,0t,0r/data=CiwiJgokCWeqOyo7eCPAETh3cFu0hiPAGVxp7S1rVULAIVnrvdbgXELAQgIIAToDCgEwQgIIAEoICJfn8a8FEAA?authuser=0 | D8: 1 | E8: LandBank | G8: 2047 | J8: 196 | K8: NORDESTE I | L8: MARECHAL DEODORO | M8: AL | N8: BURITI GARDEN PRIME | O8: Parceria | P8: 0 | Q8: Condominio | R8: Sim | S8: 2026 | T8: 46203 | U8: 0.5086 | V8: 0.3642 | W8: =SUM(U8:V8) -> 0.8728 | X8: 0.05 | Y8: 0.09 | Z8: 0.068 | AA8: 0.198 | AB8: 0.1272 | AC8: =AI8*AJ8 -> 160666.8 | AE8: =P8/10^6 -> 0 | AF8: =IF(AL8=0,0,AE8/AL8) -> 0 | AG8: =(AH8*AI8*AJ8)/10^6 -> 41.773368 | AH8: 260 | AI8: 246.8 | AJ8: 651 | AK8: 1100 | AL8: =(AK8*AJ8*AI8)/10^6 -> 176.73348 | AM8: =AL8*U8 -> 89.886648 | AN8: =AI8*AK8 -> 271480 | AO8: =AH8*AI8 -> 64168 | AP8: =U8+AB8 -> 0.6358 | AQ8: =AL8*AP8/(AG8+AE8) -> 2.6899231 | AR8: A lançar
A9: MAP033 | B9: BURITI GARDEN PRIME LOTES COMERCIAIS | D9: Ativo | E9: LandBank | K9: NORDESTE I | L9: MARECHAL DEODORO | M9: AL | N9: BURITI GARDEN PRIME LOTES COMERCIAIS | O9: Parceria | P9: 0 | Q9: Condominio | R9: Sim | S9: 2026 | T9: 46203 | U9: 0.5086 | V9: 0.3642 | W9: =SUM(U9:V9) -> 0.8728 | X9: 0.05 | Y9: 0.09 | Z9: 0.068 | AA9: 0.198 | AB9: 0.1272 | AC9: =AI9*AJ9 -> 17948.6 | AE9: =P9/10^6 -> 0 | AF9: =IF(AL9=0,0,AE9/AL9) -> 0 | AG9: =(AH9*AI9*AJ9)/10^6 -> 4.666636 | AH9: 260 | AI9: 527.9 | AJ9: 34 | AK9: 1800 | AL9: =(AK9*AJ9*AI9)/10^6 -> 32.30748 | AM9: =AL9*U9 -> 16.431584 | AN9: =AI9*AK9 -> 950220 | AO9: =AH9*AI9 -> 137254 | AP9: =U9+AB9 -> 0.6358 | AQ9: =AL9*AP9/(AG9+AE9) -> 4.4016923 | AR9: A lançar
A10: MAP034 | B10: RESIDENCIAL CIDADE JARDIM III - RIO LARGO | C10: https://earth.google.com/web/search/RIO+LARGO/@-9.52900304,-35.81653115,112.35298923a,4987.59724811d,35y,0.00000121h,0t,0r/data=CiwiJgokCbfopBmzfCPAEeMgyVIMhiPAGTrKKDMX6kHAIcF9G6ro7kHAQgIIAToDCgEwQgIIAEoICJfn8a8FEAA?authuser=0 | D10: 1 | E10: LandBank | G10: 2049 | J10: 197 | K10: NORDESTE I | L10: RIO LARGO | M10: AL | N10: RESIDENCIAL CIDADE JARDIM III | O10: Compra e Venda | P10: 1923793.1 | Q10: Loteamento | R10: Sim | S10: 2026 | T10: 46264 | U10: 0.8 | W10: =SUM(U10:V10) -> 0.8 | AA10: 0.198 | AB10: 0.2 | AC10: =AI10*AJ10 -> 525997.68 | AE10: =P10/10^6 -> 1.9237931 | AF10: =IF(AL10=0,0,AE10/AL10) -> 0.0069007876 | AG10: =(AH10*AI10*AJ10)/10^6 -> 63.119722 | AH10: 120 | AI10: 164.58 | AJ10: 3196 | AK10: 530 | AL10: =(AK10*AJ10*AI10)/10^6 -> 278.77877 | AM10: =AL10*U10 -> 223.02302 | AN10: =AI10*AK10 -> 87227.4 | AO10: =AH10*AI10 -> 19749.6 | AP10: =U10+AB10 -> 1 | AQ10: =AL10*AP10/(AG10+AE10) -> 4.2860348 | AR10: A lançar
A11: MAP035 | B11: RESIDENCIAL JARDIM AMERICA II - PENEDO | C11: https://earth.google.com/web/search/Penedo,+AL/@-10.25735808,-36.57115779,78.36658822a,3198.69005319d,35y,0h,0t,0r/data=CiwiJgokCSEY7vitZSLAEUE54MEYuCPAGb-vF-6sm0HAIR2ubXgmSkLAQgIIAToDCgEwQgIIAEoICJfn8a8FEAA?authuser=0 | D11: 1 | E11: LandBank | G11: 2048 | J11: 200 | K11: NORDESTE I | L11: PENEDO | M11: AL | N11: RESIDENCIAL JARDIM AMERICA II | O11: Compra e Venda | P11: 4000000 | Q11: Loteamento | R11: Sim | S11: 2026 | T11: 46203 | U11: 0.8 | W11: =SUM(U11:V11) -> 0.8 | AA11: 0.198 | AB11: 0.2 | AC11: =AI11*AJ11 -> 117415.64 | AE11: =P11/10^6 -> 4 | AF11: =IF(AL11=0,0,AE11/AL11) -> 0.079225609 | AG11: =(AH11*AI11*AJ11)/10^6 -> 11.741564 | AH11: 100 | AI11: 207.81529 | AJ11: 565 | AK11: 430 | AL11: =(AK11*AJ11*AI11)/10^6 -> 50.488725 | AM11: =AL11*U11 -> 40.39098 | AN11: =AI11*AK11 -> 89360.576 | AO11: =AH11*AI11 -> 20781.529 | AP11: =U11+AB11 -> 1 | AQ11: =AL11*AP11/(AG11+AE11) -> 3.2073513 | AR11: Lançado
A12: MAP038 | B12: JARDIM TROPICAL - CRATO | C12: https://earth.google.com/web/search/CRATO/@-7.23451766,-39.35968774,395.14410239a,4808.57124561d,35y,0h,0t,0r/data=CiwiJgokCREenKRkwgvAEaRMcJe6-AvAGbMRrrPsyUPAIf7hsFbW0EPAQgIIAToDCgEwQgIIAEoICJfn8a8FEAA?authuser=0 | D12: 1 | E12: LandBank | G12: 2053 | J12: 204 | K12: NORDESTE II | L12: CRATO | M12: CE | N12: JARDIM TROPICAL | O12: Compra e Venda | P12: 750000 | Q12: Loteamento | R12: Sim | S12: 2026 | T12: 46295 | U12: 0.725 | V12: 0.275 | W12: =SUM(U12:V12) -> 1 | X12: 0.05 | Y12: 0 | Z12: 0.068 | AA12: 0.198 | AC12: =AI12*AJ12 -> 188078 | AE12: =P12/10^6 -> 0.75 | AF12: =IF(AL12=0,0,AE12/AL12) -> 0.0066461787 | AG12: =(AH12*AI12*AJ12)/10^6 -> 22.56936 | AH12: 120 | AI12: 206 | AJ12: 913 | AK12: 600 | AL12: =(AK12*AJ12*AI12)/10^6 -> 112.8468 | AM12: =AL12*U12 -> 81.81393 | AN12: =AI12*AK12 -> 123600 | AO12: =AH12*AI12 -> 24720 | AP12: =U12+AB12 -> 0.725 | AQ12: =AL12*AP12/(AG12+AE12) -> 3.5084123 | AR12: A lançar
A13: MAP039 | B13: JARDIM TROPICAL - ITAPIPOCA | C13: https://earth.google.com/web/search/ITAPIPOCA/@-3.48318447,-39.60453858,85.75014124a,4591.68380015d,35y,0h,0t,0r/data=CiwiJgokCSj18Ul83hfAEYrTwO0U8hfAGYnj-uRdJETAIcMsoPJeKUTAQgIIAToDCgEwQgIIAEoICJfn8a8FEAA?authuser=0 | D13: 1 | E13: LandBank | G13: 2054 | J13: 205 | K13: NORDESTE II | L13: ITAPIPOCA | M13: CE | N13: JARDIM TROPICAL | O13: Compra e Venda | P13: 750000 | Q13: Loteamento | R13: Sim | S13: 2026 | T13: 46295 | U13: 0.8 | V13: 0.2 | W13: =SUM(U13:V13) -> 1 | X13: 0.05 | Y13: 0 | Z13: 0.068 | AA13: 0.198 | AC13: =AI13*AJ13 -> 186384 | AE13: =P13/10^6 -> 0.75 | AF13: =IF(AL13=0,0,AE13/AL13) -> 0.0080479011 | AG13: =(AH13*AI13*AJ13)/10^6 -> 24.789072 | AH13: 133 | AI13: 176 | AJ13: 1059 | AK13: 500 | AL13: =(AK13*AJ13*AI13)/10^6 -> 93.192 | AM13: =AL13*U13 -> 74.5536 | AN13: =AI13*AK13 -> 88000 | AO13: =AH13*AI13 -> 23408 | AP13: =U13+AB13 -> 0.8 | AQ13: =AL13*AP13/(AG13+AE13) -> 2.9191977 | AR13: A lançar
A14: MAP041 | B14: RESIDENCIAL CIDADE JARDIM - BALSAS | C14: https://earth.google.com/web/search/BALSAS/@-7.55676262,-46.08364445,276.35723714a,5135.12989945d,35y,0h,0t,0r/data=CiwiJgokCeJxBz6CxDDAEQlwGFeXzDDAGfey9riu6UXAIWSXkF1C8kXAQgIIAToDCgEwQgIIAEoICJfn8a8FEAA?authuser=0 | D14: 1 | E14: LandBank | F14: REVER PROJETOS | G14: 2052 | J14: 209 | K14: NORDESTE II | L14: BALSAS | M14: MA | N14: RESIDENCIAL CIDADE JARDIM I - STP1 | O14: Parceria | P14: 0 | Q14: Loteamento | R14: Sim | S14: 2026 | T14: 46387 | U14: 0.8 | V14: 0.2 | W14: =SUM(U14:V14) -> 1 | X14: 0.05 | Y14: 0 | Z14: 0.068 | AA14: 0.198 | AC14: =AI14*AJ14 -> 306340 | AE14: =P14/10^6 -> 0 | AF14: =IF(AL14=0,0,AE14/AL14) -> 0 | AG14: =(AH14*AI14*AJ14)/10^6 -> 36.7608 | AH14: 120 | AI14: 265 | AJ14: 1156 | AK14: 500 | AL14: =(AK14*AJ14*AI14)/10^6 -> 153.17 | AM14: =AL14*U14 -> 122.536 | AN14: =AI14*AK14 -> 132500 | AO14: =AH14*AI14 -> 31800 | AP14: =U14+AB14 -> 0.8 | AQ14: =AL14*AP14/(AG14+AE14) -> 3.3333333 | AR14: A lançar
A15: MAP008 | B15: CIDADE JARDIM III - SUBETAPA 1 - SANTARÉM | C15: https://earth.google.com/web/search/CIDADE+JARDIM+12+-+PARAUAPEBAS/@-2.45795692,-54.77217012,46.50042218a,6405.178905d,35y,-0h,0t,0r/data=CiwiJgokCdmVqMeMyQbAESVW3mJaMwnAGYI6tUF7jUfAIaCAQToN3EfAQgIIAToDCgEwQgIIAEoICJfn8a8FEAA | D15: 1 | E15: LandBank | G15: 2121 | J15: 147 | K15: NORTE | L15: SANTARÉM | M15: PA | N15: RESIDENCIAL CIDADE JARDIM III | O15: Aquisição de Cotas | P15: 4800000 | Q15: Loteamento | R15: Sim | S15: 2026 | T15: 46387 | U15: 1 | W15: =SUM(U15:V15) -> 1 | AA15: 0.198 | AC15: =AI15*AJ15 -> 538153.29 | AE15: =P15/10^6 -> 4.8 | AF15: =IF(AL15=0,0,AE15/AL15) -> 0.013722141 | AG15: =(AH15*AI15*AJ15)/10^6 -> 71.628203 | AH15: 133.1 | AI15: 279.27 | AJ15: 1927 | AK15: 650 | AL15: =(AK15*AJ15*AI15)/10^6 -> 349.79964 | AM15: =AL15*U15 -> 349.79964 | AN15: =AI15*AK15 -> 181525.5 | AO15: =AH15*AI15 -> 37170.837 | AP15: =U15+AB15 -> 1 | AQ15: =AL15*AP15/(AG15+AE15) -> 4.5768398 | AR15: A lançar
A16: MAP012 | B16: RESIDENCIAL JARDIM IPIRANGA II - XINGUARA | C16: https://earth.google.com/web/search/RESIDENCIAL+JARDIM+IPIRANGA+II+-+XINGUARA/@-7.12104404,-49.92523395,224.47331647a,1424.00240818d,35y,-0h,0t,0r/data=CiwiJgokCUUfzO5U4h_AEV26WHYzKSDAGfKhedaB80jAITi3e0FBEEnAQgIIAToDCgEwQgIIAEoICJfn8a8FEAA?authuser=0 | D16: 1 | E16: LandBank | G16: 2118 | J16: 152 | K16: NORTE | L16: XINGUARA | M16: PA | N16: RESIDENCIAL JARDIM IPIRANGA II | O16: Compra e Venda | P16: 13000000 | Q16: Loteamento | R16: Sim | S16: 2026 | T16: 46387 | U16: 1 | W16: =SUM(U16:V16) -> 1 | AA16: 0.198 | AC16: =AI16*AJ16 -> 195570.85 | AE16: =P16/10^6 -> 13 | AF16: =IF(AL16=0,0,AE16/AL16) -> 0.15458622 | AG16: =(AH16*AI16*AJ16)/10^6 -> 26.03048 | AH16: 133.1 | AI16: 210.97179 | AJ16: 927 | AK16: 430 | AL16: =(AK16*AJ16*AI16)/10^6 -> 84.095466 | AM16: =AL16*U16 -> 84.095466 | AN16: =AI16*AK16 -> 90717.87 | AO16: =AH16*AI16 -> 28080.345 | AP16: =U16+AB16 -> 1 | AQ16: =AL16*AP16/(AG16+AE16) -> 2.1546101 | AR16: A lançar
A17: MAP108 | B17: RESIDENCIAL CIDADE JARDIM I - CÁCERES | C17: https://earth.google.com/web/search/C%c3%81CERES/@-16.11433068,-57.66517767,145.36941085a,5953.03993857d,35y,-0h,0t,0r/data=CiwiJgokCQX_JH53NS3AETlJC9e-RS3AGdinZMrzwEzAIeq1E4h_yUzAQgIIAToDCgEwQgIIAEoICJfn8a8FEAA?authuser=0 | D17: 1 | E17: LandBank | G17: 1865 | J17: 336 | K17: OESTE | L17: CÁCERES | M17: MT | N17: RESIDENCIAL CIDADE JARDIM I | O17: Parceria | P17: 0 | Q17: Loteamento | R17: Sim | S17: 2026 | T17: 46295 | U17: 0.81 | V17: 0.19 | W17: =SUM(U17:V17) -> 1 | X17: 0.05 | Y17: 0 | Z17: 0.068 | AA17: 0.198 | AC17: =AI17*AJ17 -> 338165 | AE17: =P17/10^6 -> 0 | AF17: =IF(AL17=0,0,AE17/AL17) -> 0 | AG17: =(AH17*AI17*AJ17)/10^6 -> 44.975945 | AH17: 133 | AI17: 235 | AJ17: 1439 | AK17: 450 | AL17: =(AK17*AJ17*AI17)/10^6 -> 152.17425 | AM17: =AL17*U17 -> 123.26114 | AN17: =AI17*AK17 -> 105750 | AO17: =AH17*AI17 -> 31255 | AP17: =U17+AB17 -> 0.81 | AQ17: =AL17*AP17/(AG17+AE17) -> 2.7406015 | AR17: A lançar
A18: MAP049 | B18: RESIDENCIAL JARDIM EUROPA - COND. - DUQUE DE CAXIAS | C18: https://earth.google.com/web/search/Duque+de+Caxias,+RJ/@-22.62573879,-43.25838279,18.39588858a,1961.37171176d,35y,0h,0t,0r/data=CiwiJgokCUvDRSzvbjbAEZpP4J6LfDbAGco2nMkqO0bAIdAPxNEhSkbAQgIIAToDCgEwQgIIAEoICJfn8a8FEAA?authuser=0 | D18: 1 | E18: LandBank | G18: 2274 | J18: 224 | K18: SUDESTE | L18: DUQUE DE CAXIAS | M18: RJ | N18: RESIDENCIAL JARDIM EUROPA - COND. | O18: Permuta | P18: 166666.66 | Q18: Condominio | R18: - | S18: 2026 | T18: 46295 | U18: 0.64169 | V18: 0.3 | W18: =SUM(U18:V18) -> 0.94169 | X18: 0.05 | Y18: 0 | Z18: 0.068 | AA18: 0.198 | AB18: 0.05831 | AC18: =AI18*AJ18 -> 220580 | AE18: =P18/10^6 -> 0.16666666 | AF18: =IF(AL18=0,0,AE18/AL18) -> 0.00094447967 | AG18: =(AH18*AI18*AJ18)/10^6 -> 39.7044 | AH18: 180 | AI18: 410 | AJ18: 538 | AK18: 800 | AL18: =(AK18*AJ18*AI18)/10^6 -> 176.464 | AM18: =AL18*U18 -> 113.23518 | AN18: =AI18*AK18 -> 328000 | AO18: =AH18*AI18 -> 73800 | AP18: =U18+AB18 -> 0.7 | AQ18: =AL18*AP18/(AG18+AE18) -> 3.0981062 | AR18: A lançar
A19: MAP068 | B19: RESIDENCIAL SÃO FRANCISCO DE AVARÉ - AVARÉ | C19: https://earth.google.com/web/search/Avar%c3%a9,+SP/@-23.13817295,-48.93466362,759.5009067a,2026.71010604d,35y,0h,0t,0r/data=CiwiJgokCbdqOrTERTTAEdFka3GySTTAGdvcUdEVIUnAIfMq4hhXJUnAQgIIAToDCgEwQgIIAEoICJfn8a8FEAA?authuser=0 | D19: 1 | E19: LandBank | G19: 2270 | J19: 262 | K19: SUDESTE | L19: AVARÉ | M19: SP | N19: RESIDENCIAL SÃO FRANCISCO DE AVARÉ | O19: Parceria | P19: 0 | Q19: Loteamento | R19: Sim | S19: 2026 | T19: 46295 | U19: 0.6417 | V19: 0.3 | W19: =SUM(U19:V19) -> 0.9417 | X19: 0.05 | Y19: 0.09 | Z19: 0.068 | AA19: 0.198 | AB19: 0.0583 | AC19: =AI19*AJ19 -> 132640.2 | AE19: =P19/10^6 -> 0 | AF19: =IF(AL19=0,0,AE19/AL19) -> 0 | AG19: =(AH19*AI19*AJ19)/10^6 -> 21.620353 | AH19: 163 | AI19: 219.24 | AJ19: 605 | AK19: 600 | AL19: =(AK19*AJ19*AI19)/10^6 -> 79.58412 | AM19: =AL19*U19 -> 51.06913 | AN19: =AI19*AK19 -> 131544 | AO19: =AH19*AI19 -> 35736.12 | AP19: =U19+AB19 -> 0.7 | AQ19: =AL19*AP19/(AG19+AE19) -> 2.5766871 | AR19: A lançar
A20: MAP079 | B20: 3DA - POA/CALHA DE PEDRA I - PORTO ALEGRE | C20: https://earth.google.com/web/search/PORTO+ALEGRE/@-30.11127632,-51.12148809,52.85283914a,2914.98585346d,35y,0.00000001h,0t,0r/data=CiwiJgokCdF8eOBcqz3AEVk4mQ0orz3AGW7M2FWxNkrAIVpN-_QgO0rAQgIIAToDCgEwQgIIAEoICJfn8a8FEAA?authuser=0 | D20: 1 | E20: LandBank | G20: 2381 | J20: 290 | K20: SUL | L20: PORTO ALEGRE | M20: RS | N20: 3DA - POA/CALHA DE PEDRA I | O20: Parceria | P20: 0 | Q20: Loteamento | R20: Sim | S20: 2026 | T20: 46387 | U20: 0.328 | V20: 0.18 | W20: =SUM(U20:V20) -> 0.508 | X20: 0.07 | Y20: 0.07 | Z20: 0.068 | AA20: 0.198 | AB20: 0.492 | AC20: =AI20*AJ20 -> 91258 | AE20: =P20/10^6 -> 0 | AF20: =IF(AL20=0,0,AE20/AL20) -> 0 | AG20: =(AH20*AI20*AJ20)/10^6 -> 15.97015 | AH20: 175 | AI20: 206 | AJ20: 443 | AK20: 750 | AL20: =(AK20*AJ20*AI20)/10^6 -> 68.4435 | AM20: =AL20*U20 -> 22.449468 | AN20: =AI20*AK20 -> 154500 | AO20: =AH20*AI20 -> 36050 | AP20: =U20+AB20 -> 0.82 | AQ20: =AL20*AP20/(AG20+AE20) -> 3.5142857 | AR20: A lançar
A21: MAP080 | B21: 4A - SANTA CRUZ DO SUL - SANTA CRUZ DO SUL | C21: https://earth.google.com/web/search/SANTA+CRUZ+DO+SUL/@-29.67679798,-52.44461427,171.97361515a,2440.82594259d,35y,0h,0t,0r/data=CiwiJgokCfCOoxjmrj3AEQTSMIMEsz3AGejaJMRHlUnAIb28UugYmknAQgIIAToDCgEwQgIIAEoICJfn8a8FEAA?authuser=0 | D21: 1 | E21: LandBank | G21: 2394 | J21: 293 | K21: SUL | L21: SANTA CRUZ DO SUL | M21: RS | N21: 4A - SANTA CRUZ DO SUL | O21: Parceria | P21: 0 | Q21: Loteamento | R21: Sim | S21: 2026 | T21: 46295 | U21: 0.544 | V21: 0.32 | W21: =SUM(U21:V21) -> 0.864 | X21: 0.07 | Y21: 0.095 | Z21: 0.068 | AA21: 0.198 | AB21: 0.136 | AC21: =AI21*AJ21 -> 103037 | AE21: =P21/10^6 -> 0 | AF21: =IF(AL21=0,0,AE21/AL21) -> 0 | AG21: =(AH21*AI21*AJ21)/10^6 -> 18.031475 | AH21: 175 | AI21: 323 | AJ21: 319 | AK21: 700 | AL21: =(AK21*AJ21*AI21)/10^6 -> 72.1259 | AM21: =AL21*U21 -> 39.23649 | AN21: =AI21*AK21 -> 226100 | AO21: =AH21*AI21 -> 56525 | AP21: =U21+AB21 -> 0.68 | AQ21: =AL21*AP21/(AG21+AE21) -> 2.72 | AR21: A lançar
A22: MAP082 | B22: 5A - SÃO LEOPOLDO - ABERTO 1ºFASE - SÃO LEOPOLDO | C22: https://earth.google.com/web/search/S%c3%83O+LEOPOLDO/@-29.69124438,-51.18506887,72.72392941a,2763.99436261d,35y,0h,0t,0r/data=CiwiJgokCYgGRBoKGD7AEeRabSOjGz7AGfvFjOgUgEnAIaI5Hn1OhEnAQgIIAToDCgEwQgIIAEoICJfn8a8FEAA?authuser=0 | D22: 1 | E22: LandBank | G22: 2387 | J22: 295 | K22: SUL | L22: SÃO LEOPOLDO | M22: RS | N22: 5A -SÃO LEOPOLDO - ABERTO 1ºFASE | O22: Permuta | P22: 2215500 | Q22: Loteamento | R22: Sim | S22: 2026 | T22: 46203 | U22: 0.556 | V22: 0.305 | W22: =SUM(U22:V22) -> 0.861 | X22: 0.07 | Y22: 0 | Z22: 0.068 | AA22: 0.198 | AB22: 0.139 | AC22: =AI22*AJ22 -> 130830 | AE22: =P22/10^6 -> 2.2155 | AF22: =IF(AL22=0,0,AE22/AL22) -> 0.021167737 | AG22: =(AH22*AI22*AJ22)/10^6 -> 22.89525 | AH22: 175 | AI22: 267 | AJ22: 490 | AK22: 800 | AL22: =(AK22*AJ22*AI22)/10^6 -> 104.664 | AM22: =AL22*U22 -> 58.193184 | AN22: =AI22*AK22 -> 213600 | AO22: =AH22*AI22 -> 46725 | AP22: =U22+AB22 -> 0.695 | AQ22: =AL22*AP22/(AG22+AE22) -> 2.8968263 | AR22: A lançar
A23: MAP084 | B23: 5B - SÃO LEOPOLDO - FECHADO 1ºFASE - SÃO LEOPOLDO | C23: https://earth.google.com/web/search/S%c3%83O+LEOPOLDO/@-29.69124438,-51.18506887,72.72392941a,2763.99436261d,35y,0h,0t,0r/data=CiwiJgokCYgGRBoKGD7AEeRabSOjGz7AGfvFjOgUgEnAIaI5Hn1OhEnAQgIIAToDCgEwQgIIAEoICJfn8a8FEAA?authuser=0 | D23: 1 | E23: LandBank | G23: 2387 | J23: 297 | K23: SUL | L23: SÃO LEOPOLDO | M23: RS | N23: 5B -SÃO LEOPOLDO - FECHADO 1ºFASE | O23: Permuta | P23: 2215500 | Q23: Condominio | R23: Sim | S23: 2026 | T23: 46203 | U23: 0.556 | V23: 0.305 | W23: =SUM(U23:V23) -> 0.861 | X23: 0.07 | Y23: 0 | Z23: 0.068 | AA23: 0.198 | AB23: 0.139 | AC23: =AI23*AJ23 -> 101592 | AE23: =P23/10^6 -> 2.2155 | AF23: =IF(AL23=0,0,AE23/AL23) -> 0.014538546 | AG23: =(AH23*AI23*AJ23)/10^6 -> 35.5572 | AH23: 350 | AI23: 332 | AJ23: 306 | AK23: 1500 | AL23: =(AK23*AJ23*AI23)/10^6 -> 152.388 | AM23: =AL23*U23 -> 84.727728 | AN23: =AI23*AK23 -> 498000 | AO23: =AH23*AI23 -> 116200 | AP23: =U23+AB23 -> 0.695 | AQ23: =AL23*AP23/(AG23+AE23) -> 2.8038679 | AR23: A lançar
A24: MAP087 | B24: 6B - CX. SUL - SIVIERO / CAMINHOS DO SOL - CAXIAS DO SUL | C24: https://earth.google.com/web/search/CAXIAS+DO+SUL/@-29.13850338,-51.12230837,798.77655109a,2732.24624327d,35y,-0h,0t,0r/data=CnwaThJICiUweDk1MWViY2QxNjQzNWYwNzM6MHhmNTE0ZjcwN2I1NzczYmY0GVOObimMLD3AIRz3nKoxl0nAKg1DQVhJQVMgRE8gU1VMGAEgASImCiQJ1tRH0utLPcARa0Tc7klTPcAZjiIdAINaScAhKwpGrRhjScBCAggBOgMKATBCAggASggIl-fxrwUQAA?authuser=0 | D24: 1 | E24: LandBank | G24: 2374 | J24: 300 | K24: SUL | L24: CAXIAS DO SUL | M24: RS | N24: 6B - CX. SUL - SIVIERO / CAMINHOS DO SOL | O24: Parceria | P24: 0 | Q24: Loteamento | R24: Sim | S24: 2026 | T24: 46203 | U24: 0.4 | V24: 0.5 | W24: =SUM(U24:V24) -> 0.9 | X24: 0.07 | Y24: 0.095 | Z24: 0.068 | AA24: 0.198 | AB24: 0.1 | AC24: =AI24*AJ24 -> 264827.8 | AE24: =P24/10^6 -> 0 | AF24: =IF(AL24=0,0,AE24/AL24) -> 0 | AG24: =(AH24*AI24*AJ24)/10^6 -> 46.344865 | AH24: 175 | AI24: 432.72516 | AJ24: 612 | AK24: 900 | AL24: =(AK24*AJ24*AI24)/10^6 -> 238.34502 | AM24: =AL24*U24 -> 95.338008 | AN24: =AI24*AK24 -> 389452.65 | AO24: =AH24*AI24 -> 75726.904 | AP24: =U24+AB24 -> 0.5 | AQ24: =AL24*AP24/(AG24+AE24) -> 2.5714286 | AR24: A lançar
A25: MAP088 | B25: 6C - CX. SUL - SIVIERO / VALE DAS COLINAS - CAXIAS DO SUL | C25: https://earth.google.com/web/search/CAXIAS+DO+SUL/@-29.13038377,-51.22227002,696.92023901a,2558.98775459d,35y,0h,0t,0r/data=CnwaThJICiUweDk1MWViY2QxNjQzNWYwNzM6MHhmNTE0ZjcwN2I1NzczYmY0GVOObimMLD3AIRz3nKoxl0nAKg1DQVhJQVMgRE8gU1VMGAEgASImCiQJ1tRH0utLPcARa0Tc7klTPcAZjiIdAINaScAhKwpGrRhjScBCAggBOgMKATBCAggASggIl-fxrwUQAA?authuser=0 | D25: 1 | E25: LandBank | G25: 2374 | J25: 301 | K25: SUL | L25: CAXIAS DO SUL | M25: RS | N25: 6C - CX. SUL - SIVIERO / VALE DAS COLINAS | O25: Parceria | P25: 0 | Q25: Loteamento | R25: Sim | S25: 2026 | T25: 46387 | U25: 0.4 | V25: 0.5 | W25: =SUM(U25:V25) -> 0.9 | X25: 0.07 | Y25: 0.095 | Z25: 0.068 | AA25: 0.198 | AB25: 0.1 | AC25: =AI25*AJ25 -> 159307.14 | AE25: =P25/10^6 -> 0 | AF25: =IF(AL25=0,0,AE25/AL25) -> 0 | AG25: =(AH25*AI25*AJ25)/10^6 -> 27.87875 | AH25: 175 | AI25: 375.72439 | AJ25: 424 | AK25: 800 | AL25: =(AK25*AJ25*AI25)/10^6 -> 127.44571 | AM25: =AL25*U25 -> 50.978285 | AN25: =AI25*AK25 -> 300579.51 | AO25: =AH25*AI25 -> 65751.768 | AP25: =U25+AB25 -> 0.5 | AQ25: =AL25*AP25/(AG25+AE25) -> 2.2857143 | AR25: A lançar
A26: MAP094 | B26: 8B - VIAMÃO - SURREAX/MONTAINE - VIAMÃO | C26: https://earth.google.com/web/search/VIAM%c3%83O/@-30.06497491,-51.03875844,59.46189546a,2897.51328111d,35y,360h,0t,0r/data=CnYaSBJCCiUweDk1MTk5OGE2ZDhmMjY0NDE6MHgxNWY0MmRhYTgyYjY2ZDQwGXCFZo0wFT7AIQB4nz5dhEnAKgdWSUFNw4NPGAEgASImCiQJsTk0ZNOlP8ARLqkiuNytP8AZ9eUZULQnSsAh8JLJOEwxSsBCAggBOgMKATBCAggASggIl-fxrwUQAA?authuser=0 | D26: 1 | E26: LandBank | G26: 2388 | J26: 310 | K26: SUL | L26: VIAMÃO | M26: RS | N26: 8B - VIAMÃO - SURREAX/MONTAINE | O26: Parceria | P26: 0 | Q26: Loteamento | R26: - | S26: 2026 | T26: 46203 | U26: 0.544 | V26: 0.32 | W26: =SUM(U26:V26) -> 0.864 | X26: 0.07 | Y26: 0.095 | Z26: 0.068 | AA26: 0.198 | AB26: 0.136 | AC26: =AI26*AJ26 -> 84153.46 | AE26: =P26/10^6 -> 0 | AF26: =IF(AL26=0,0,AE26/AL26) -> 0 | AG26: =(AH26*AI26*AJ26)/10^6 -> 14.726856 | AH26: 175 | AI26: 235.06553 | AJ26: 358 | AK26: 650 | AL26: =(AK26*AJ26*AI26)/10^6 -> 54.699749 | AM26: =AL26*U26 -> 29.756663 | AN26: =AI26*AK26 -> 152792.59 | AO26: =AH26*AI26 -> 41136.468 | AP26: =U26+AB26 -> 0.68 | AQ26: =AL26*AP26/(AG26+AE26) -> 2.5257143 | AR26: Lançado
A27: MAP097 | B27: 9B - PELOTAS - INDUSTRIAL RCL - PELOTAS | C27: https://earth.google.com/web/search/PELOTAS/@-31.66345999,-52.34766459,33.86198261a,5500.41331546d,35y,0h,0t,0r/data=CiwiJgokCcTGFe60DEDAEbD1lg7sD0DAGcKY98kGFErAITOrTYO9G0rAQgIIAToDCgEwQgIIAEoICJfn8a8FEAA?authuser=0 | D27: 1 | E27: LandBank | G27: 2380 | J27: 313 | K27: SUL | L27: PELOTAS | M27: RS | N27: 9B - PELOTAS - INDUSTRIAL RCL | O27: Parceria | P27: 0 | Q27: Loteamento | R27: Sim | S27: 2026 | T27: 46203 | U27: 0.552 | V27: 0.31 | W27: =SUM(U27:V27) -> 0.862 | X27: 0.07 | Y27: 0.095 | Z27: 0.068 | AA27: 0.198 | AB27: 0.138 | AC27: =AI27*AJ27 -> 64704 | AE27: =P27/10^6 -> 0 | AF27: =IF(AL27=0,0,AE27/AL27) -> 0 | AG27: =(AH27*AI27*AJ27)/10^6 -> 9.05856 | AH27: 140 | AI27: 1348 | AJ27: 48 | AK27: 900 | AL27: =(AK27*AJ27*AI27)/10^6 -> 58.2336 | AM27: =AL27*U27 -> 32.144947 | AN27: =AI27*AK27 -> 1213200 | AO27: =AH27*AI27 -> 188720 | AP27: =U27+AB27 -> 0.69 | AQ27: =AL27*AP27/(AG27+AE27) -> 4.4357143 | AR27: A lançar
A28: MAP103 | B28: 14A - GUARAPUAVA - 41HA (ELDORADO I) - GUARAPUAVA | C28: https://earth.google.com/web/search/GUARAPUAVA/@-25.39953824,-51.52751542,1024.00734861a,2854.44336804d,35y,360h,0t,0r/data=CiwiJgokCbN0uAN0-znAEZYMuK9MojrAGTg0o7y1VEjAIWKVrBNVEknAQgIIAToDCgEwQgIIAEoICJfn8a8FEAA?authuser=0 | D28: 1 | E28: LandBank | G28: 2378 | J28: 322 | K28: SUL | L28: GUARAPUAVA | M28: PR | N28: 15a- Guarapuava - 41ha (Eldorado I) | O28: Parceria | P28: 0 | Q28: Loteamento | R28: Sim | S28: 2026 | T28: 46295 | U28: 0.536 | V28: 0.33 | W28: =SUM(U28:V28) -> 0.866 | X28: 0.07 | Y28: 0.095 | Z28: 0.068 | AA28: 0.198 | AB28: 0.134 | AC28: =AI28*AJ28 -> 167783.24 | AE28: =P28/10^6 -> 0 | AF28: =IF(AL28=0,0,AE28/AL28) -> 0 | AG28: =(AH28*AI28*AJ28)/10^6 -> 29.362067 | AH28: 175 | AI28: 191.97167 | AJ28: 874 | AK28: 650 | AL28: =(AK28*AJ28*AI28)/10^6 -> 109.05911 | AM28: =AL28*U28 -> 58.455681 | AN28: =AI28*AK28 -> 124781.59 | AO28: =AH28*AI28 -> 33595.042 | AP28: =U28+AB28 -> 0.67 | AQ28: =AL28*AP28/(AG28+AE28) -> 2.4885714 | AR28: A lançar
A29: MAP104 | B29: 14B - GUARAPUAVA - 24HA (ELDORADO II) - GUARAPUAVA | C29: https://earth.google.com/web/search/GUARAPUAVA/@-25.39953824,-51.52751542,1024.00734861a,2854.44336804d,35y,360h,0t,0r/data=CiwiJgokCbN0uAN0-znAEZYMuK9MojrAGTg0o7y1VEjAIWKVrBNVEknAQgIIAToDCgEwQgIIAEoICJfn8a8FEAA?authuser=0 | D29: 1 | E29: LandBank | G29: 2379 | J29: 323 | K29: SUL | L29: GUARAPUAVA | M29: PR | N29: 15b-Guarapuava - 24ha (Eldorado II) | O29: Parceria | P29: 0 | Q29: Loteamento | R29: Sim | S29: 2026 | T29: 46295 | U29: 0.52 | V29: 0.35 | W29: =SUM(U29:V29) -> 0.87 | X29: 0.07 | Y29: 0.095 | Z29: 0.068 | AA29: 0.198 | AB29: 0.13 | AC29: =AI29*AJ29 -> 96232 | AE29: =P29/10^6 -> 0 | AF29: =IF(AL29=0,0,AE29/AL29) -> 0 | AG29: =(AH29*AI29*AJ29)/10^6 -> 16.8406 | AH29: 175 | AI29: 184 | AJ29: 523 | AK29: 650 | AL29: =(AK29*AJ29*AI29)/10^6 -> 62.5508 | AM29: =AL29*U29 -> 32.526416 | AN29: =AI29*AK29 -> 119600 | AO29: =AH29*AI29 -> 32200 | AP29: =U29+AB29 -> 0.65 | AQ29: =AL29*AP29/(AG29+AE29) -> 2.4142857 | AR29: A lançar
A30: MAP021 | B30: ARSO 191 - PALMAS | C30: https://earth.google.com/web/search/Palmas/@-10.25056053,-48.33726188,252.56505595a,47484.59826451d,35y,0h,0t,0r/data=CnQaRhJACiQweDkzM2IzNDM5OTExZjEyNTc6MHg5M2I4MDcwZDA1YzgxOGYZtHQF24h_JMAhUsd0MoIpSMAqBlBhbG1hcxgCIAEiJgokCZ4TQp4rbCTAEd7oz8tIyyTAGZMBVXzHEEjAIR-xYc3lQUjAQgIIAToDCgEwQgIIAEoICJfn8a8FEAA?authuser=0 | D30: 1 | E30: LandBank | G30: PENDENCIA | J30: 162 | K30: TOCANTINS | L30: PALMAS | M30: TO | N30: ARSO 191 | O30: Parceria | P30: 0 | Q30: Loteamento | R30: Sim | S30: 2026 | T30: 46203 | U30: 0.3696 | W30: =SUM(U30:V30) -> 0.3696 | AA30: 0.198 | AB30: 0.6304 | AC30: =AI30*AJ30 -> 224990.22 | AE30: =P30/10^6 -> 0 | AF30: =IF(AL30=0,0,AE30/AL30) -> 0 | AG30: =(AH30*AI30*AJ30)/10^6 -> 28.798748 | AH30: 128 | AI30: 290.68504 | AJ30: 774 | AK30: 550 | AL30: =(AK30*AJ30*AI30)/10^6 -> 123.74462 | AM30: =AL30*U30 -> 45.736012 | AN30: =AI30*AK30 -> 159876.77 | AO30: =AH30*AI30 -> 37207.685 | AP30: =U30+AB30 -> 1 | AQ30: =AL30*AP30/(AG30+AE30) -> 4.296875 | AR30: A lançar
A31: MAP023 | B31: JARDIM CALIFORNIA - PALMAS | C31: https://earth.google.com/web/search/Palmas,+TO/@-10.1436093,-48.30385159,263.38670878a,3734.01843008d,35y,0h,0t,0r/data=CngaShJECiQweDkzM2IzNDM5OTExZjEyNTc6MHg5M2I4MDcwZDA1YzgxOGYZtHQF24h_JMAhUsd0MoIpSMAqClBhbG1hcywgVE8YASABIiYKJAnKmUn74gAbwBGE16-ZZBobwBm4d1Wa5ohJwCHUhDGVbI9JwEICCAE6AwoBMEICCABKCAiX5_GvBRAA?authuser=0 | D31: 1 | E31: LandBank | G31: PENDENCIA | J31: 184 | K31: TOCANTINS | L31: PALMAS | M31: TO | N31: JARDIM CALIFORNIA (JCF) | O31: Parceria | P31: 0 | Q31: Loteamento | R31: Sim | S31: 2026 | T31: 46660 | U31: 0.6 | W31: =SUM(U31:V31) -> 0.6 | AA31: 0.198 | AB31: 0.4 | AC31: =AI31*AJ31 -> 158850 | AE31: =P31/10^6 -> 0 | AF31: =IF(AL31=0,0,AE31/AL31) -> 0 | AG31: =(AH31*AI31*AJ31)/10^6 -> 20.3328 | AH31: 128 | AI31: 225 | AJ31: 706 | AK31: 500 | AL31: =(AK31*AJ31*AI31)/10^6 -> 79.425 | AM31: =AL31*U31 -> 47.655 | AN31: =AI31*AK31 -> 112500 | AO31: =AH31*AI31 -> 28800 | AP31: =U31+AB31 -> 1 | AQ31: =AL31*AP31/(AG31+AE31) -> 3.90625 | AR31: A lançar
A32: MAP024 | B32: RESIDENCIAL ACSV (ÁREA DO PASTOR) - PALMAS | C32: https://earth.google.com/web/search/Palmas/@-10.26832599,-48.31559059,242.67876446a,47835.63394664d,35y,360h,0t,0r/data=CnQaRhJACiQweDkzM2IzNDM5OTExZjEyNTc6MHg5M2I4MDcwZDA1YzgxOGYZtHQF24h_JMAhUsd0MoIpSMAqBlBhbG1hcxgBIAEiJgokCZ4TQp4rbCTAEd7oz8tIyyTAGZMBVXzHEEjAIR-xYc3lQUjAQgIIAToDCgEwQgIIAEoICJfn8a8FEAA?authuser=0 | D32: 1 | E32: LandBank | G32: PENDENCIA | J32: 185 | K32: TOCANTINS | L32: PALMAS | M32: TO | N32: RESIDENCIAL ACSV (MARCO ANTONIO) | O32: Parceria | P32: 0 | Q32: Loteamento | R32: - | S32: 2026 | T32: 46387 | U32: 0.69 | W32: =SUM(U32:V32) -> 0.69 | AA32: 0.198 | AB32: 0.31 | AC32: =AI32*AJ32 -> 327445 | AE32: =P32/10^6 -> 0 | AF32: =IF(AL32=0,0,AE32/AL32) -> 0 | AG32: =(AH32*AI32*AJ32)/10^6 -> 41.91296 | AH32: 128 | AI32: 215 | AJ32: 1523 | AK32: 600 | AL32: =(AK32*AJ32*AI32)/10^6 -> 196.467 | AM32: =AL32*U32 -> 135.56223 | AN32: =AI32*AK32 -> 129000 | AO32: =AH32*AI32 -> 27520 | AP32: =U32+AB32 -> 1 | AQ32: =AL32*AP32/(AG32+AE32) -> 4.6875 | AR32: A lançar
A33: MAP030 | B33: LOTEAMENTO VISTA DO LAGO - FORMOSA | C33: https://earth.google.com/web/search/FORMOSA/@-15.58172122,-47.32794355,897.72742465a,4704.42149765d,35y,0.00000085h,0t,0r/data=CiwiJgokCWIPaQHJuSfAEafTOxpW8SjAGfzlyTCsKUbAIT9JW4C_y0bAQgIIAToDCgEwQgIIAEoICJfn8a8FEAA?authuser=0 | D33: 1 | E33: LandBank | G33: 2039 | J33: 192 | K33: TOCANTINS | L33: FORMOSA | M33: GO | N33: LOTEAMENTO VISTA DO LAGO | O33: Parceria | P33: 0 | Q33: Loteamento | R33: sim | S33: 2026 | T33: 46203 | U33: 0.6 | V33: 0.3 | W33: =SUM(U33:V33) -> 0.9 | X33: 0.05 | Y33: 0.095 | Z33: 0.068 | AA33: 0.198 | AB33: 0.1 | AC33: =AI33*AJ33 -> 168948.74 | AE33: =P33/10^6 -> 0 | AF33: =IF(AL33=0,0,AE33/AL33) -> 0 | AG33: =(AH33*AI33*AJ33)/10^6 -> 21.625439 | AH33: 128 | AI33: 291.29093 | AJ33: 580 | AK33: 650 | AL33: =(AK33*AJ33*AI33)/10^6 -> 109.81668 | AM33: =AL33*U33 -> 65.890009 | AN33: =AI33*AK33 -> 189339.11 | AO33: =AH33*AI33 -> 37285.239 | AP33: =U33+AB33 -> 0.7 | AQ33: =AL33*AP33/(AG33+AE33) -> 3.5546875 | AR33: Lançado
A34: MAP030 | B34: VEREDAS DO LAGO | D34: Ativo | E34: LandBank | K34: TOCANTINS | L34: FORMOSA | M34: GO | N34: VEREDAS DO LAGO | O34: Condominio | P34: - | Q34: Condominio | R34: - | S34: 2026 | T34: 46337 | W34: 0.41 | AA34: 0.35 | AB34: 0.05 | AC34: =AI34*AJ34 -> 128100 | AG34: =(AH34*AI34*AJ34)/10^6 -> 16.3968 | AH34: 128 | AI34: 300 | AJ34: 427 | AK34: 1600 | AL34: =(AK34*AJ34*AI34)/10^6 -> 204.96 | AM34: =AL34*U34 -> 0 | AN34: =AI34*AK34 -> 480000 | AO34: =AH34*AI34 -> 38400 | AP34: =U34+AB34 -> 0.05 | AQ34: =AL34*AP34/(AG34+AE34) -> 0.625 | AR34: A lançar
A35: MAP025 | B35: LOTE PÉ DA PONTE - LUZIMANGUES | C35: https://earth.google.com/web/search/LUZIMANGUES/@-10.2185028,-48.49860748,262.65133073a,44260.3323794d,35y,0h,0t,0r/data=CnoaTBJGCiUweDkzMjRiMjViZWUyY2MyOTU6MHg0MjNiYjhkNzhhZDI2MjdkGWy2TUxyYyTAIa1f-qjQO0jAKgtMVVpJTUFOR1VFUxgBIAEiJgokCc4UM1nC9iPAEZt0OQ_dzCTAGbN2lxLzDEjAIXeF7rCEe0jAQgIIAToDCgEwQgIIAEoICJfn8a8FEAA?authuser=0 | D35: 1 | E35: LandBank | G35: 2315 | J35: 188 | K35: TOCANTINS | L35: LUZIMANGUES | M35: TO | N35: LOTE PÉ DA PONTE | O35: Parceria | P35: 0 | Q35: Loteamento | R35: - | S35: 2026 | T35: 46387 | U35: 0.5323 | W35: =SUM(U35:V35) -> 0.5323 | AA35: 0.198 | AB35: 0.4677 | AC35: =AI35*AJ35 -> 14607 | AE35: =P35/10^6 -> 0 | AF35: =IF(AL35=0,0,AE35/AL35) -> 0 | AG35: =(AH35*AI35*AJ35)/10^6 -> 1.16856 | AH35: 80 | AI35: 14607 | AJ35: 1 | AK35: 500 | AL35: =(AK35*AJ35*AI35)/10^6 -> 7.3035 | AM35: =AL35*U35 -> 3.887653 | AN35: =AI35*AK35 -> 7303500 | AO35: =AH35*AI35 -> 1168560 | AP35: =U35+AB35 -> 1 | AQ35: =AL35*AP35/(AG35+AE35) -> 6.25 | AR35: A lançar
A36: MAP143 | B36: A DEFINIR | D36: Ativo | E36: LandBank | K36: SUL | L36: PASSO FUNDO | M36: RS | N36: 14 - Passo Fundo - Logística | O36: Parceria | Q36: Loteamento | R36: - | S36: 2026 | T36: 46331 | W36: 0.4 | Y36: 0.07 | AA36: 0.5 | AB36: 0.1 | AC36: =AI36*AJ36 -> 249604.85 | AE36: 0 | AF36: 0 | AG36: 127 | AH36: 220 | AI36: 2496.0485 | AJ36: 100 | AK36: 800 | AL36: =(AK36*AJ36*AI36)/10^6 -> 199.68388 | AM36: =AL36*U36 -> 0 | AN36: =AI36*AK36 -> 1996838.8 | AO36: =AH36*AI36 -> 549130.67 | AP36: =U36+AB36 -> 0.1 | AQ36: =AL36*AP36/(AG36+AE36) -> 0.1572314 | AR36: A lançar
A37: MAP122 | B37: JARDIM DO CERRADO 10 - GOIÂNIA | C37: https://earth.google.com/web/search/GOI%c3%82NIA/@-16.67746594,-49.42770992,858.01737984a,4789.30417081d,35y,9.31126662h,0.18897674t,360r/data=CiwiJgokCTImrsNH8yrAEajobj-t-irAGWOHbhWxkEjAIXn8jCOOlEjAQgIIAToDCgEwQgIIAEoICJfn8a8FEAA?authuser=0 | D37: 1 | E37: LandBank | G37: 2770 | J37: 364 | K37: CENTRO-OESTE II | L37: GOIÂNIA | M37: GO | N37: JARDIM DO CERRADO 10 | O37: Parceria | P37: 0 | Q37: Loteamento | R37: - | S37: 2027 | T37: 46752 | U37: 0.8 | W37: =SUM(U37:V37) -> 0.8 | AA37: 0.198 | AB37: 0.2 | AC37: =AI37*AJ37 -> 214171.94 | AE37: =P37/10^6 -> 0 | AF37: =IF(AL37=0,0,AE37/AL37) -> 0 | AG37: =(AH37*AI37*AJ37)/10^6 -> 31.697447 | AH37: 148 | AI37: 428.34388 | AJ37: 500 | AK37: 500 | AL37: =(AK37*AJ37*AI37)/10^6 -> 107.08597 | AM37: =AL37*U37 -> 85.668776 | AN37: =AI37*AK37 -> 214171.94 | AO37: =AH37*AI37 -> 63394.894 | AP37: =U37+AB37 -> 1 | AQ37: =AL37*AP37/(AG37+AE37) -> 3.3783784 | AR37: A lançar
A38: MAP125 | B38: RESIDENCIAL PAINEIRAS | D38: 1 | E38: LandBank | G38: 2177 | K38: CENTRO-OESTE II | L38: PORTO VELHO | M38: RO | N38: RESIDENCIAL PAINEIRAS | O38: Parceria | P38: 0 | Q38: Loteamento | R38: Sim | S38: 2027 | T38: - | U38: 0.8 | W38: =SUM(U38:V38) -> 0.8 | AA38: 0.198 | AB38: 0.2 | AC38: =AI38*AJ38 -> 363235.45 | AE38: =P38/10^6 -> 0 | AF38: =IF(AL38=0,0,AE38/AL38) -> 0 | AG38: =(AH38*AI38*AJ38)/10^6 -> 48.346638 | AH38: 133.1 | AI38: 215.57 | AJ38: 1685 | AK38: 380 | AL38: =(AK38*AJ38*AI38)/10^6 -> 138.02947 | AM38: =AL38*U38 -> 110.42358 | AN38: =AI38*AK38 -> 81916.6 | AO38: =AH38*AI38 -> 28692.367 | AP38: =U38+AB38 -> 1 | AQ38: =AL38*AP38/(AG38+AE38) -> 2.8549962 | AR38: A lançar
A39: MAP032 | B39: RESIDENCIAL ALTO DAS BARAUNAS II - ARAPIRACA | C39: https://earth.google.com/web/search/ARAPIRACA/@-9.74896182,-36.69647245,245.55478327a,4738.09539736d,35y,0h,0t,0r/data=CiwiJgokCclCL3e0IS_AESFNk5j5MS_AGZRIeMyvpUfAIcPoSk9ErkfAQgIIAToDCgEwQgIIAEoICJfn8a8FEAA?authuser=0 | D39: 1 | E39: LandBank | G39: 2045 | J39: 194 | K39: NORDESTE I | L39: ARAPIRACA | M39: AL | N39: RESIDENCIAL ALTO DAS BARAUNAS II | O39: Parceria | P39: 0 | Q39: Loteamento | R39: - | S39: 2027 | T39: 46568 | U39: 0.5304 | V39: 0.337 | W39: =SUM(U39:V39) -> 0.8674 | X39: 0.05 | Y39: 0.09 | Z39: 0.068 | AA39: 0.198 | AB39: 0.1326 | AC39: =AI39*AJ39 -> 169253.49 | AE39: =P39/10^6 -> 0 | AF39: =IF(AL39=0,0,AE39/AL39) -> 0 | AG39: =(AH39*AI39*AJ39)/10^6 -> 20.310419 | AH39: 120 | AI39: 187.64245 | AJ39: 902 | AK39: 426.10642 | AL39: =(AK39*AJ39*AI39)/10^6 -> 72.12 | AM39: =AL39*U39 -> 38.252448 | AN39: =AI39*AK39 -> 79955.654 | AO39: =AH39*AI39 -> 22517.094 | AP39: =U39+AB39 -> 0.663 | AQ39: =AL39*AP39/(AG39+AE39) -> 2.354238 | AR39: A lançar
A40: MAP037 | B40: RESIDENCIAL JARDIM EUROPA - BARRA DOS COQUEIROS | C40: https://earth.google.com/web/search/BARRA+DOS+COQUEIROS/@-10.86709266,-36.98473154,9.11625276a,6838.59037115d,35y,0h,0t,0r/data=CiwiJgokCez0LUwI4RzAEc6AbPlB_xzAGXUWKXAsqkPAIYL6q2XpsUPAQgIIAToDCgEwQgIIAEoICJfn8a8FEAA?authuser=0 | D40: 1 | E40: LandBank | G40: 2046 | J40: 202 | K40: NORDESTE I | L40: BARRA DOS COQUEIROS | M40: SE | N40: RESIDENCIAL JARDIM EUROPA | O40: Compra e Venda | P40: 4000000 | Q40: Loteamento | R40: - | S40: 2027 | T40: 46568 | U40: 0.8 | W40: =SUM(U40:V40) -> 0.8 | AA40: 0.198 | AB40: 0.2 | AC40: =AI40*AJ40 -> 389286.32 | AE40: =P40/10^6 -> 4 | AF40: =IF(AL40=0,0,AE40/AL40) -> 0.023895845 | AG40: =(AH40*AI40*AJ40)/10^6 -> 46.714359 | AH40: 120 | AI40: 216.27018 | AJ40: 1800 | AK40: 430 | AL40: =(AK40*AJ40*AI40)/10^6 -> 167.39312 | AM40: =AL40*U40 -> 133.9145 | AN40: =AI40*AK40 -> 92996.177 | AO40: =AH40*AI40 -> 25952.422 | AP40: =U40+AB40 -> 1 | AQ40: =AL40*AP40/(AG40+AE40) -> 3.3007046 | AR40: A lançar
...

Sheet Painel
D2: EMPREENDIMENTOS | F2: =COUNTA(AREAS!N4:N233) -> 230
D3: CIDADE | F3: =COUNTA(_xlfn.UNIQUE(AREAS!L4:L233)) -> 74
D4: ESTADOS | F4: =COUNTA(_xlfn.UNIQUE(AREAS!M4:M233)) -> 17
D5: UNIDADES (LOTES) | F5: =SUM(AREAS!AJ4:AJ233) -> 209316.38
D6: ÁREA HECTARE | F6: =G6/10000 -> 5467.7119 | G6: =SUM(AREAS!AC4:AC233) -> 54677119
D7: VGV TOTAL | F7: =SUM(AREAS!AL4:AL233) -> 36570.203
D8: VGV BT | F8: =SUM(AREAS!AM4:AM233) -> 23444.781
B10: Regional | C10: Empreendimentos | D10: Loteamento | E10: Condominio | F10: Qtde lotes | G10: Loteamento | H10: Condominio | I10: % Cond
B11: {=_xlfn._xlws.SORT(_xlfn.UNIQUE(AREAS!K4:K167))} -> CENTRO-OESTE I | C11: =COUNTIF(AREAS!K:K,Painel!B11) -> 2 | D11: =COUNTIFS(AREAS!$K:$K,Painel!$B11,AREAS!$Q:$Q,Painel!D$10) -> 2 | E11: =COUNTIFS(AREAS!$K:$K,Painel!$B11,AREAS!$Q:$Q,Painel!E$10) -> 0 | F11: =SUMIFS(AREAS!$AJ$4:$AJ$1048576,AREAS!$K$4:$K$1048576,Painel!B11) -> 1461 | G11: =SUMIFS(AREAS!$AJ$4:$AJ$167,AREAS!$K$4:$K$167,Painel!$B11,AREAS!$Q$4:$Q$167,Painel!G$10) -> 1461 | H11: =SUMIFS(AREAS!$AJ$4:$AJ$167,AREAS!$K$4:$K$167,Painel!$B11,AREAS!$Q$4:$Q$167,Painel!H$10) -> 0 | I11: =H11/F11 -> 0
B12: CENTRO-OESTE II | C12: =COUNTIF(AREAS!K:K,Painel!B12) -> 10 | D12: =COUNTIFS(AREAS!$K:$K,Painel!$B12,AREAS!$Q:$Q,Painel!D$10) -> 10 | E12: =COUNTIFS(AREAS!$K:$K,Painel!$B12,AREAS!$Q:$Q,Painel!E$10) -> 0 | F12: =SUMIFS(AREAS!$AJ$4:$AJ$1048576,AREAS!$K$4:$K$1048576,Painel!B12) -> 9416 | G12: =SUMIFS(AREAS!$AJ$4:$AJ$167,AREAS!$K$4:$K$167,Painel!$B12,AREAS!$Q$4:$Q$167,Painel!G$10) -> 8916 | H12: =SUMIFS(AREAS!$AJ$4:$AJ$167,AREAS!$K$4:$K$167,Painel!$B12,AREAS!$Q$4:$Q$167,Painel!H$10) -> 0 | I12: =H12/F12 -> 0
B13: NORDESTE I | C13: =COUNTIF(AREAS!K:K,Painel!B13) -> 7 | D13: =COUNTIFS(AREAS!$K:$K,Painel!$B13,AREAS!$Q:$Q,Painel!D$10) -> 5 | E13: =COUNTIFS(AREAS!$K:$K,Painel!$B13,AREAS!$Q:$Q,Painel!E$10) -> 2 | F13: =SUMIFS(AREAS!$AJ$4:$AJ$1048576,AREAS!$K$4:$K$1048576,Painel!B13) -> 8189.6667 | G13: =SUMIFS(AREAS!$AJ$4:$AJ$167,AREAS!$K$4:$K$167,Painel!$B13,AREAS!$Q$4:$Q$167,Painel!G$10) -> 7504.6667 | H13: =SUMIFS(AREAS!$AJ$4:$AJ$167,AREAS!$K$4:$K$167,Painel!$B13,AREAS!$Q$4:$Q$167,Painel!H$10) -> 685 | I13: =H13/F13 -> 0.083641988
B14: NORDESTE II | C14: =COUNTIF(AREAS!K:K,Painel!B14) -> 7 | D14: =COUNTIFS(AREAS!$K:$K,Painel!$B14,AREAS!$Q:$Q,Painel!D$10) -> 7 | E14: =COUNTIFS(AREAS!$K:$K,Painel!$B14,AREAS!$Q:$Q,Painel!E$10) -> 0 | F14: =SUMIFS(AREAS!$AJ$4:$AJ$1048576,AREAS!$K$4:$K$1048576,Painel!B14) -> 7420 | G14: =SUMIFS(AREAS!$AJ$4:$AJ$167,AREAS!$K$4:$K$167,Painel!$B14,AREAS!$Q$4:$Q$167,Painel!G$10) -> 7420 | H14: =SUMIFS(AREAS!$AJ$4:$AJ$167,AREAS!$K$4:$K$167,Painel!$B14,AREAS!$Q$4:$Q$167,Painel!H$10) -> 0 | I14: =H14/F14 -> 0
B15: NORTE | C15: =COUNTIF(AREAS!K:K,Painel!B15) -> 26 | D15: =COUNTIFS(AREAS!$K:$K,Painel!$B15,AREAS!$Q:$Q,Painel!D$10) -> 25 | E15: =COUNTIFS(AREAS!$K:$K,Painel!$B15,AREAS!$Q:$Q,Painel!E$10) -> 1 | F15: =SUMIFS(AREAS!$AJ$4:$AJ$1048576,AREAS!$K$4:$K$1048576,Painel!B15) -> 23843 | G15: =SUMIFS(AREAS!$AJ$4:$AJ$167,AREAS!$K$4:$K$167,Painel!$B15,AREAS!$Q$4:$Q$167,Painel!G$10) -> 22093 | H15: =SUMIFS(AREAS!$AJ$4:$AJ$167,AREAS!$K$4:$K$167,Painel!$B15,AREAS!$Q$4:$Q$167,Painel!H$10) -> 250 | I15: =H15/F15 -> 0.010485258
B16: OESTE | C16: =COUNTIF(AREAS!K:K,Painel!B16) -> 32 | D16: =COUNTIFS(AREAS!$K:$K,Painel!$B16,AREAS!$Q:$Q,Painel!D$10) -> 24 | E16: =COUNTIFS(AREAS!$K:$K,Painel!$B16,AREAS!$Q:$Q,Painel!E$10) -> 8 | F16: =SUMIFS(AREAS!$AJ$4:$AJ$1048576,AREAS!$K$4:$K$1048576,Painel!B16) -> 44711.364 | G16: =SUMIFS(AREAS!$AJ$4:$AJ$167,AREAS!$K$4:$K$167,Painel!$B16,AREAS!$Q$4:$Q$167,Painel!G$10) -> 33674.697 | H16: =SUMIFS(AREAS!$AJ$4:$AJ$167,AREAS!$K$4:$K$167,Painel!$B16,AREAS!$Q$4:$Q$167,Painel!H$10) -> 6639.6667 | I16: =H16/F16 -> 0.14850065
B17: SUDESTE | C17: =COUNTIF(AREAS!K:K,Painel!B17) -> 63 | D17: =COUNTIFS(AREAS!$K:$K,Painel!$B17,AREAS!$Q:$Q,Painel!D$10) -> 54 | E17: =COUNTIFS(AREAS!$K:$K,Painel!$B17,AREAS!$Q:$Q,Painel!E$10) -> 9 | F17: =SUMIFS(AREAS!$AJ$4:$AJ$1048576,AREAS!$K$4:$K$1048576,Painel!B17) -> 53031 | G17: =SUMIFS(AREAS!$AJ$4:$AJ$167,AREAS!$K$4:$K$167,Painel!$B17,AREAS!$Q$4:$Q$167,Painel!G$10) -> 27857 | H17: =SUMIFS(AREAS!$AJ$4:$AJ$167,AREAS!$K$4:$K$167,Painel!$B17,AREAS!$Q$4:$Q$167,Painel!H$10) -> 1460 | I17: =H17/F17 -> 0.027531067
B18: SUL | C18: =COUNTIF(AREAS!K:K,Painel!B18) -> 58 | D18: =COUNTIFS(AREAS!$K:$K,Painel!$B18,AREAS!$Q:$Q,Painel!D$10) -> 51 | E18: =COUNTIFS(AREAS!$K:$K,Painel!$B18,AREAS!$Q:$Q,Painel!E$10) -> 7 | F18: =SUMIFS(AREAS!$AJ$4:$AJ$1048576,AREAS!$K$4:$K$1048576,Painel!B18) -> 40619.667 | G18: =SUMIFS(AREAS!$AJ$4:$AJ$167,AREAS!$K$4:$K$167,Painel!$B18,AREAS!$Q$4:$Q$167,Painel!G$10) -> 19134.5 | H18: =SUMIFS(AREAS!$AJ$4:$AJ$167,AREAS!$K$4:$K$167,Painel!$B18,AREAS!$Q$4:$Q$167,Painel!H$10) -> 444 | I18: =H18/F18 -> 0.010930666
B19: TOCANTINS | C19: =COUNTIF(AREAS!K:K,Painel!B19) -> 34 | D19: =COUNTIFS(AREAS!$K:$K,Painel!$B19,AREAS!$Q:$Q,Painel!D$10) -> 29 | E19: =COUNTIFS(AREAS!$K:$K,Painel!$B19,AREAS!$Q:$Q,Painel!E$10) -> 5 | F19: =SUMIFS(AREAS!$AJ$4:$AJ$1048576,AREAS!$K$4:$K$1048576,Painel!B19) -> 24917.685 | G19: =SUMIFS(AREAS!$AJ$4:$AJ$167,AREAS!$K$4:$K$167,Painel!$B19,AREAS!$Q$4:$Q$167,Painel!G$10) -> 19544.556 | H19: =SUMIFS(AREAS!$AJ$4:$AJ$167,AREAS!$K$4:$K$167,Painel!$B19,AREAS!$Q$4:$Q$167,Painel!H$10) -> 427 | I19: =H19/F19 -> 0.017136423
B20: Total | C20: =SUM(C11:C19) -> 239 | D20: =SUM(D11:D19) -> 207 | E20: =SUM(E11:E19) -> 32 | F20: =SUM(F11:F19) -> 213609.38 | G20: =SUM(G11:G19) -> 147605.42 | H20: =SUM(H11:H19) -> 9905.6667

Sheet Excluído da base
A2: MAP034 | B2: RESIDENCIAL CIDADE JARDIM III - STP 3 - RIO LARGO | C2: https://earth.google.com/web/search/RIO+LARGO/@-9.52900304,-35.81653115,112.35298923a,4987.59724811d,35y,0.00000121h,0t,0r/data=CiwiJgokCbfopBmzfCPAEeMgyVIMhiPAGTrKKDMX6kHAIcF9G6ro7kHAQgIIAToDCgEwQgIIAEoICJfn8a8FEAA?authuser=0 | D2: 1 | E2: LandBank | G2: 2049 | J2: 199 | K2: NORDESTE I | L2: RIO LARGO | M2: AL | N2: RESIDENCIAL CIDADE JARDIM III - STP 3 | O2: Compra e Venda | P2: 1923792 | Q2: Loteamento | R2: Sim | S2: 2028 | T2: 46934 | U2: 0.8 | W2: =SUM(U2:V2) -> 0.8 | AA2: 0.198 | AB2: 0.2 | AC2: =AI2*AJ2 -> 114840 | AE2: =P2/10^6 -> 1.923792 | AF2: =IF(AL2=0,0,AE2/AL2) -> 0.035444897 | AG2: =(AH2*AI2*AJ2)/10^6 -> 13.7808 | AH2: 120 | AI2: 165 | AJ2: 696 | AK2: 472.61904 | AL2: =(AK2*AJ2*AI2)/10^6 -> 54.275571 | AM2: =AL2*U2 -> 43.420457 | AN2: 79872.618 | AO2: =AH2*AI2 -> 19800 | AP2: =U2+AB2 -> 1 | AQ2: =AL2*AP2/(AG2+AE2) -> 3.4560319 | AR2: A lançar
A3: MAP034 | B3: RESIDENCIAL CIDADE JARDIM III - STP 2 - RIO LARGO | C3: https://earth.google.com/web/search/RIO+LARGO/@-9.52900304,-35.81653115,112.35298923a,4987.59724811d,35y,0.00000121h,0t,0r/data=CiwiJgokCbfopBmzfCPAEeMgyVIMhiPAGTrKKDMX6kHAIcF9G6ro7kHAQgIIAToDCgEwQgIIAEoICJfn8a8FEAA?authuser=0 | D3: 1 | E3: LandBank | G3: 2049 | J3: 198 | K3: NORDESTE I | L3: RIO LARGO | M3: AL | N3: RESIDENCIAL CIDADE JARDIM III | O3: Compra e Venda | P3: 1923792 | Q3: Loteamento | R3: Sim | S3: 2027 | T3: 46477 | U3: 0.8 | W3: =SUM(U3:V3) -> 0.8 | AA3: 0.198 | AB3: 0.2 | AC3: =AI3*AJ3 -> 165000 | AE3: =P3/10^6 -> 1.923792 | AF3: =IF(AL3=0,0,AE3/AL3) -> 0.024669648 | AG3: =(AH3*AI3*AJ3)/10^6 -> 19.8 | AH3: 120 | AI3: 165 | AJ3: 1000 | AK3: 472.61904 | AL3: =(AK3*AJ3*AI3)/10^6 -> 77.982142 | AM3: =AL3*U3 -> 62.385714 | AN3: 79872.618 | AO3: =AH3*AI3 -> 19800 | AP3: =U3+AB3 -> 1 | AQ3: =AL3*AP3/(AG3+AE3) -> 3.5897113 | AR3: A lançar
A4: MAP037 | B4: RESIDENCIAL JARDIM EUROPA - BARRA DOS COQUEIROS | C4: https://earth.google.com/web/search/BARRA+DOS+COQUEIROS/@-10.86709266,-36.98473154,9.11625276a,6838.59037115d,35y,0h,0t,0r/data=CiwiJgokCez0LUwI4RzAEc6AbPlB_xzAGXUWKXAsqkPAIYL6q2XpsUPAQgIIAToDCgEwQgIIAEoICJfn8a8FEAA?authuser=0 | D4: 1 | E4: LandBank | G4: 2046 | J4: 203 | K4: NORDESTE I | L4: BARRA DOS COQUEIROS | M4: SE | N4: RESIDENCIAL JARDIM EUROPA | O4: Compra e Venda | P4: 4000000 | Q4: Loteamento | R4: - | S4: 2028 | T4: 46934 | U4: 0.8 | W4: =SUM(U4:V4) -> 0.8 | AA4: 0.198 | AB4: 0.2 | AC4: =AI4*AJ4 -> 204159.05 | AE4: =P4/10^6 -> 4 | AF4: =IF(AL4=0,0,AE4/AL4) -> 0.045564111 | AG4: =(AH4*AI4*AJ4)/10^6 -> 24.499086 | AH4: 120 | AI4: 216.49952 | AJ4: 943 | AK4: 430 | AL4: =(AK4*AJ4*AI4)/10^6 -> 87.788391 | AM4: =AL4*U4 -> 70.230713 | AN4: 93094.795 | AO4: =AH4*AI4 -> 25979.943 | AP4: =U4+AB4 -> 1 | AQ4: =AL4*AP4/(AG4+AE4) -> 3.0803932 | AR4: A lançar
A5: MAP106 | B5: RESIDENCIAL CIDADE JARDIM II - STP 2 - RIO BRANCO | C5: https://earth.google.com/web/search/RIO+BRANCO/@-9.9098996,-67.78102104,162.15508008a,8113.58158257d,35y,360h,0t,0r/data=CnkaSxJFCiUweDkxN2Y3YmI2OGFjYzk2ZjM6MHg4YWI4OGYxZDdmMWQ5YjNjGbb6RWSz8iPAIUaLfRPU81DAKgpSSU8gQlJBTkNPGAEgASImCiQJfzD99xEWMMAR4w_EqB0hMMAZ8L7dRwvPTMAhtzjkj7naTMBCAggBOgMKATBCAggASggIl-fxrwUQAA?authuser=0 | D5: 1 | E5: LandBank | G5: 2106 | J5: 327 | K5: OESTE | L5: RIO BRANCO | M5: AC | N5: RESIDENCIAL CIDADE JARDIM II - STP 2 | O5: Compra e Venda | P5: 1436252.3 | Q5: Loteamento | R5: Sim | S5: 2027 | T5: 46568 | U5: 0.7 | V5: 0.3 | W5: =SUM(U5:V5) -> 1 | X5: 0.05 | Y5: 0.09 | Z5: 0.068 | AA5: 0.198 | AC5: =AI5*AJ5 -> 248211 | AE5: =P5/10^6 -> 1.4362523 | AF5: =IF(AL5=0,0,AE5/AL5) -> 0.011572834 | AG5: =(AH5*AI5*AJ5)/10^6 -> 39.71376 | AH5: 160 | AI5: 261 | AJ5: 951 | AK5: 500 | AL5: =(AK5*AJ5*AI5)/10^6 -> 124.1055 | AM5: =AL5*U5 -> 86.87385 | AN5: 110000 | AO5: =AH5*AI5 -> 41760 | AP5: =U5+AB5 -> 0.7 | AQ5: =AL5*AP5/(AG5+AE5) -> 2.11115 | AR5: A lançar
A6: MAP108 | B6: RESIDENCIAL CIDADE JARDIM I - STP2 - CÁCERES | C6: https://earth.google.com/web/search/C%c3%81CERES/@-16.11433068,-57.66517767,145.36941085a,5953.03993857d,35y,-0h,0t,0r/data=CiwiJgokCQX_JH53NS3AETlJC9e-RS3AGdinZMrzwEzAIeq1E4h_yUzAQgIIAToDCgEwQgIIAEoICJfn8a8FEAA?authuser=0 | D6: 1 | E6: LandBank | G6: 1865 | J6: 337 | K6: OESTE | L6: CÁCERES | M6: MT | N6: RESIDENCIAL CIDADE JARDIM I - STP2 | O6: Parceria | P6: 0 | Q6: Loteamento | R6: Sim | S6: 2026 | T6: 46295 | U6: 0.81 | V6: 0.19 | W6: =SUM(U6:V6) -> 1 | X6: 0.05 | Y6: 0 | Z6: 0.068 | AA6: 0.198 | AC6: 169349 | AE6: =P6/10^6 -> 0 | AF6: =IF(AL6=0,0,AE6/AL6) -> 0 | AG6: =(AH6*AI6*AJ6)/10^6 -> 22.567972 | AH6: 133 | AI6: 236 | AJ6: 719 | AK6: 450 | AL6: =(AK6*AJ6*AI6)/10^6 -> 76.3578 | AM6: =AL6*U6 -> 61.849818 | AN6: 90000 | AO6: =AH6*AI6 -> 31388 | AP6: =U6+AB6 -> 0.81 | AQ6: =AL6*AP6/(AG6+AE6) -> 2.7406015 | AR6: A lançar
A7: MAP126 | B7: RESIDENCIAL PARQUE JARDIM | D7: 1 | E7: LandBank | G7: 2588 | K7: OESTE | L7: TANGARÁ DA SERRA | M7: MT | N7: RESIDENCIAL PARQUE JARDIM | O7: Compra e Venda | P7: 10682.93 | Q7: Loteamento | R7: - | S7: 2027 | T7: - | U7: 0.7 | V7: 0.3 | W7: =SUM(U7:V7) -> 1 | AA7: 0.198 | AC7: 998700 | AE7: =P7/10^6 -> 0.01068293 | AF7: =IF(AL7=0,0,AE7/AL7) -> 4.760664e-05 | AG7: =(AH7*AI7*AJ7)/10^6 -> 74.613 | AH7: 133 | AI7: 250 | AJ7: 2244 | AK7: 400 | AL7: =(AK7*AJ7*AI7)/10^6 -> 224.4 | AM7: =AL7*U7 -> 157.08 | AN7: =AI7*AK7 -> 100000 | AO7: =AH7*AI7 -> 33250 | AP7: =U7+AB7 -> 0.7 | AQ7: =AL7*AP7/(AG7+AE7) -> 2.1049618 | AR7: A lançar
A8: MAP111 | B8: RESIDENCIAL CIDADE JARDIM I - STP2 - TANGARÁ DA SERRA | C8: https://earth.google.com/web/search/TANGAR%c3%81+DA+SERRA/@-14.62032689,-57.54082084,346.92096178a,5258.20888551d,35y,0h,0t,0r/data=CiwiJgokCXA9rQptMS_AEXKWStZFPy_AGehdnQKoD0zAIeamtZ71FkzAQgIIAToDCgEwQgIIAEoICJfn8a8FEAA?authuser=0 | D8: 1 | E8: LandBank | G8: 2107 | J8: 341 | K8: OESTE | L8: TANGARÁ DA SERRA | M8: MT | N8: RESIDENCIAL CIDADE JARDIM I - STP2 | O8: Compra e Venda | P8: 10682.93 | Q8: Loteamento | R8: Sim | S8: 2029 | T8: 47483 | U8: 0.7 | V8: 0.3 | W8: =SUM(U8:V8) -> 1 | X8: 0.05 | Y8: 0.09 | Z8: 0.068 | AA8: 0.198 | AC8: =AI8*AJ8 -> 279716.51 | AE8: =P8/10^6 -> 0.01068293 | AF8: =IF(AL8=0,0,AE8/AL8) -> 7.6383979e-05 | AG8: =(AH8*AI8*AJ8)/10^6 -> 37.202296 | AH8: 133 | AI8: 324.1211 | AJ8: 863 | AK8: 500 | AL8: =(AK8*AJ8*AI8)/10^6 -> 139.85825 | AM8: =AL8*U8 -> 97.900778 | AN8: =AI8*AK8 -> 162060.55 | AO8: =AH8*AI8 -> 43108.106 | AP8: =U8+AB8 -> 0.7 | AQ8: =AL8*AP8/(AG8+AE8) -> 2.6308235 | AR8: A lançar
A9: MAP058 | B9: RESIDENCIAL CIDADE JARDIM II - ITAPETININGA | C9: https://earth.google.com/web/search/ITAPETININGA/@-23.62618263,-48.09089394,643.86218986a,3111.8044646d,35y,0h,0t,0r/data=CiwiJgokCSTz4KZOwTbAEWUEDjqixTbAGTHHXZ3oi0bAId3jN-OskEbAQgIIAToDCgEwQgIIAEoICJfn8a8FEAA?authuser=0 | D9: 1 | E9: LandBank | G9: 2277 | J9: 241 | K9: SUDESTE | L9: ITAPETININGA | M9: SP | N9: RESIDENCIAL CIDADE JARDIM II | O9: Parceria | P9: 0 | Q9: Loteamento | R9: Sim | S9: 2029 | T9: 47482 | U9: 0.55 | V9: 0.40002 | W9: =SUM(U9:V9) -> 0.95002 | X9: 0.05 | Y9: 0.09 | Z9: 0.068 | AA9: 0.198 | AB9: 0.04998 | AC9: =AI9*AJ9 -> 268822.81 | AE9: =P9/10^6 -> 0 | AF9: =IF(AL9=0,0,AE9/AL9) -> 0 | AG9: =(AH9*AI9*AJ9)/10^6 -> 43.818118 | AH9: 163 | AI9: 218.73296 | AJ9: 1229 | AK9: 550 | AL9: =(AK9*AJ9*AI9)/10^6 -> 147.85255 | AM9: =AL9*U9 -> 81.3189 | AN9: =AI9*AK9 -> 120303.13 | AO9: =AH9*AI9 -> 35653.473 | AP9: =U9+AB9 -> 0.59998 | AQ9: =AL9*AP9/(AG9+AE9) -> 2.0244724 | AR9: A lançar
A10: MAP043 | B10: RESIDENCIAL CIDADE JARDIM II - MONTES CLAROS | C10: https://earth.google.com/web/search/MONTES+CLAROS/@-16.78340211,-43.85914746,708.18079241a,4857.74891966d,35y,0h,0t,0r/data=CiwiJgokCaYkZ-ZvtTPAEWpwuK9tuzPAGWYZIm4r8UfAIR546sKi90fAQgIIAToDCgEwQgIIAEoICJfn8a8FEAA?authuser=0 | D10: 1 | E10: LandBank | G10: 2288 | J10: 214 | K10: SUDESTE | L10: MONTES CLAROS | M10: MG | N10: RESIDENCIAL CIDADE JARDIM II | O10: Parceria | P10: 0 | Q10: Loteamento | R10: - | S10: 2029 | T10: 47391 | U10: 0.45835 | V10: 0.5 | W10: =SUM(U10:V10) -> 0.95835 | X10: 0.05 | Y10: 0 | Z10: 0.068 | AA10: 0.198 | AB10: 0.04165 | AC10: =AI10*AJ10 -> 232564 | AE10: =P10/10^6 -> 0 | AF10: =IF(AL10=0,0,AE10/AL10) -> 0 | AG10: =(AH10*AI10*AJ10)/10^6 -> 37.907932 | AH10: 163 | AI10: 212 | AJ10: 1097 | AK10: 550 | AL10: =(AK10*AJ10*AI10)/10^6 -> 127.9102 | AM10: =AL10*U10 -> 58.62764 | AN10: =AI10*AK10 -> 116600 | AO10: =AH10*AI10 -> 34556 | AP10: =U10+AB10 -> 0.5 | AQ10: =AL10*AP10/(AG10+AE10) -> 1.6871166 | AR10: A lançar
A11: MAP051 | B11: RESIDENCIAL CIDADE JARDIM - ITATIAIA | C11: https://earth.google.com/web/search/Itatiaia,+RJ/@-22.45992895,-44.52068364,423.46245411a,8948.36825161d,35y,0h,0t,0r/data=CiwiJgokCZ6WBhqISi_AEVBldJnBEzjAGf8jZD_WyULAIQ_8zVvgN0zAQgIIAToDCgEwQgIIAEoICJfn8a8FEAA?authuser=0 | D11: 1 | E11: LandBank | G11: 2278 | J11: 226 | K11: SUDESTE | L11: ITATIAIA | M11: RJ | N11: RESIDENCIAL CIDADE JARDIM | O11: Parceria | P11: 0 | Q11: Loteamento | R11: Sim | S11: 2029 | T11: 47483 | U11: 0.595855 | V11: 0.35 | W11: =SUM(U11:V11) -> 0.945855 | X11: 0.05 | Y11: 0.09 | Z11: 0.068 | AA11: 0.198 | AB11: 0.054145 | AC11: =AI11*AJ11 -> 202308 | AE11: =P11/10^6 -> 0 | AF11: =IF(AL11=0,0,AE11/AL11) -> 0 | AG11: =(AH11*AI11*AJ11)/10^6 -> 32.976204 | AH11: 163 | AI11: 276 | AJ11: 733 | AK11: 715 | AL11: =(AK11*AJ11*AI11)/10^6 -> 144.65022 | AM11: =AL11*U11 -> 86.190557 | AN11: =AI11*AK11 -> 197340 | AO11: =AH11*AI11 -> 44988 | AP11: =U11+AB11 -> 0.65 | AQ11: =AL11*AP11/(AG11+AE11) -> 2.851227 | AR11: A lançar
A12: MAP046 | B12: JARDIM DO VALE III - COLATINA | C12: https://earth.google.com/web/search/COLATINA/@-19.52647784,-40.60231088,138.19641271a,3370.80950192d,35y,360h,0t,0r/data=CiwiJgokCW0IAtKljDbAEcH4TEmVtzbAGTR6r34gk0XAIZ1xJ4dpwkXAQgIIAToDCgEwQgIIAEoICJfn8a8FEAA?authuser=0 | D12: 1 | E12: LandBank | G12: 2284 | J12: 219 | K12: SUDESTE | L12: COLATINA | M12: ES | N12: JARDIM DO VALE III | O12: Parceria | P12: 0 | Q12: Loteamento | R12: - | S12: 2029 | T12: 47299 | U12: 0.504185 | V12: 0.45 | W12: =SUM(U12:V12) -> 0.954185 | X12: 0.05 | Y12: 0.09 | Z12: 0.068 | AA12: 0.198 | AB12: 0.045815 | AC12: =AI12*AJ12 -> 411540 | AE12: =P12/10^6 -> 0 | AF12: =IF(AL12=0,0,AE12/AL12) -> 0 | AG12: =(AH12*AI12*AJ12)/10^6 -> 69.9618 | AH12: 170 | AI12: 361 | AJ12: 1140 | AK12: 650 | AL12: =(AK12*AJ12*AI12)/10^6 -> 267.501 | AM12: =AL12*U12 -> 134.86999 | AN12: =AI12*AK12 -> 234650 | AO12: =AH12*AI12 -> 61370 | AP12: =U12+AB12 -> 0.55 | AQ12: =AL12*AP12/(AG12+AE12) -> 2.1029412 | AR12: A lançar
A13: MAP048 | B13: RESIDENCIAL CIDADE JARDIM III - DUQUE DE CAXIAS | C13: - | D13: 1 | E13: LandBank | G13: 2273 | J13: 223 | K13: SUDESTE | L13: DUQUE DE CAXIAS | M13: RJ | N13: RESIDENCIAL CIDADE JARDIM III | O13: Permuta | P13: 166667 | Q13: Loteamento | R13: - | S13: 2029 | T13: 47207 | U13: 0.64169 | V13: 0.3 | W13: =SUM(U13:V13) -> 0.94169 | X13: 0.05 | Y13: 0.09 | Z13: 0.068 | AA13: 0.198 | AB13: 0.05831 | AC13: =AI13*AJ13 -> 262200 | AE13: =P13/10^6 -> 0.166667 | AF13: =IF(AL13=0,0,AE13/AL13) -> 0.00079456045 | AG13: =(AH13*AI13*AJ13)/10^6 -> 42.7386 | AH13: 163 | AI13: 230 | AJ13: 1140 | AK13: 800 | AL13: =(AK13*AJ13*AI13)/10^6 -> 209.76 | AM13: =AL13*U13 -> 134.60089 | AN13: =AI13*AK13 -> 184000 | AO13: =AH13*AI13 -> 37490 | AP13: =U13+AB13 -> 0.7 | AQ13: =AL13*AP13/(AG13+AE13) -> 3.4222372 | AR13: A lançar
A14: MAP051 | B14: RESIDENCIAL CIDADE JARDIM II - ITATIAIA | C14: https://earth.google.com/web/search/Itatiaia,+RJ/@-22.45992895,-44.52068364,423.46245411a,8948.36825161d,35y,0h,0t,0r/data=CiwiJgokCZ6WBhqISi_AEVBldJnBEzjAGf8jZD_WyULAIQ_8zVvgN0zAQgIIAToDCgEwQgIIAEoICJfn8a8FEAA?authuser=0 | D14: 1 | E14: LandBank | G14: 2278 | J14: 228 | K14: SUDESTE | L14: ITATIAIA | M14: RJ | N14: RESIDENCIAL CIDADE JARDIM II | O14: Parceria | P14: 0 | Q14: Loteamento | R14: - | S14: 2029 | T14: 47483 | U14: 0.595855 | V14: 0.35 | W14: =SUM(U14:V14) -> 0.945855 | X14: 0.05 | Y14: 0.09 | Z14: 0.068 | AA14: 0.198 | AB14: 0.054145 | AC14: =AI14*AJ14 -> 220800 | AE14: =P14/10^6 -> 0 | AF14: =IF(AL14=0,0,AE14/AL14) -> 0 | AG14: =(AH14*AI14*AJ14)/10^6 -> 35.9904 | AH14: 163 | AI14: 276 | AJ14: 800 | AK14: 650 | AL14: =(AK14*AJ14*AI14)/10^6 -> 143.52 | AM14: =AL14*U14 -> 85.51711 | AN14: =AI14*AK14 -> 179400 | AO14: =AH14*AI14 -> 44988 | AP14: =U14+AB14 -> 0.65 | AQ14: =AL14*AP14/(AG14+AE14) -> 2.5920245 | AR14: A lançar
A15: MAP053 | B15: A DENIFIR - ITABORAÍ | C15: https://earth.google.com/web/search/ITABORA%c3%8d/@-22.7705662,-42.90251485,16.01615323a,2212.94452737d,35y,0h,0t,0r/data=CiwiJgokCWeuUiREWTbAEf3J2D8_YjbAGShqrBV35ETAIYuIHwFV7kTAQgIIAToDCgEwQgIIAEoICJfn8a8FEAA?authuser=0 | D15: 1 | E15: LandBank | G15: 2276 | J15: 232 | K15: SUDESTE | L15: ITABORAÍ | M15: RJ | N15: A DEFINIR | O15: Compra e Venda | P15: 6273440.6 | Q15: Loteamento | R15: - | S15: 2029 | T15: 47391 | U15: 0.573362 | V15: 0.14 | W15: =SUM(U15:V15) -> 0.713362 | X15: 0.05 | Y15: 0 | Z15: 0.068 | AA15: 0.198 | AB15: 0.286638 | AC15: =AI15*AJ15 -> 95400 | AE15: =P15/10^6 -> 6.2734406 | AF15: =IF(AL15=0,0,AE15/AL15) -> 0.10959889 | AG15: =(AH15*AI15*AJ15)/10^6 -> 15.5502 | AH15: 163 | AI15: 180 | AJ15: 530 | AK15: 600 | AL15: =(AK15*AJ15*AI15)/10^6 -> 57.24 | AM15: =AL15*U15 -> 32.819241 | AN15: =AI15*AK15 -> 108000 | AO15: =AH15*AI15 -> 29340 | AP15: =U15+AB15 -> 0.86 | AQ15: =AL15*AP15/(AG15+AE15) -> 2.2556457 | AR15: A lançar
A16: MAP054 | B16: RESIDENCIAL CIDADE JARDIM III - MACAE | C16: https://earth.google.com/web/search/MACAE/@-22.36624118,-41.8234272,34.24557963a,6150.26313789d,35y,0h,0t,0r/data=CiwiJgokCcmdsN-e6TbAEVdlXJdI9TbAGUMWAjLoEkXAIbglujnGH0XAQgIIAToDCgEwQgIIAEoICJfn8a8FEAA?authuser=0 | D16: 1 | E16: LandBank | G16: 2287 | J16: 235 | K16: SUDESTE | L16: MACAE | M16: RJ | N16: RESIDENCIAL CIDADE JARDIM III | O16: Parceria | P16: 0 | Q16: Loteamento | R16: - | S16: 2029 | T16: 47483 | U16: 0.46669 | V16: 0.3 | W16: =SUM(U16:V16) -> 0.76669 | X16: 0.05 | Y16: 0.09 | Z16: 0.068 | AA16: 0.198 | AB16: 0.23331 | AC16: 171270.39 | AE16: =P16/10^6 -> 0 | AF16: =IF(AL16=0,0,AE16/AL16) -> 0 | AG16: =(AH16*AI16*AJ16)/10^6 -> 30.82752 | AH16: 180 | AI16: 256 | AJ16: 669 | AK16: 950 | AL16: =(AK16*AJ16*AI16)/10^6 -> 162.7008 | AM16: =AL16*U16 -> 75.930836 | AN16: =AI16*AK16 -> 243200 | AO16: =AH16*AI16 -> 46080 | AP16: =U16+AB16 -> 0.7 | AQ16: =AL16*AP16/(AG16+AE16) -> 3.6944444 | AR16: A lançar
A17: MAP056 | B17: A DEFINIR I - ARRAIAL DO CABO | C17: https://earth.google.com/web/search/ARRAIAL+DO+CABO/@-22.93536918,-42.19797612,2.57990512a,8028.28875861d,35y,0h,0t,0r/data=CnwaThJICiMweDk3MTk3YmEwMTFkM2E5OjB4M2M0YTJiN2IxNGUwMDMwORnXiSarffc2wCH54BAFjgNFwCoPQVJSQUlBTCBETyBDQUJPGAEgASImCiQJ3jIbZ5OdN8AR8LcycgejN8AZIoh5YJwISMAhtPiWdKgOSMBCAggBOgMKATBCAggASggIl-fxrwUQAA?authuser=0 | D17: 1 | E17: LandBank | G17: 2269 | J17: 238 | K17: SUDESTE | L17: ARRAIAL DO CABO | M17: RJ | N17: A DEFINIR | O17: Parceria | P17: 0 | Q17: Loteamento | R17: Sim | S17: 2029 | T17: 47299 | U17: 0.6875 | V17: 0.25 | W17: =SUM(U17:V17) -> 0.9375 | X17: 0.05 | Y17: 0 | Z17: 0.068 | AA17: 0.198 | AB17: 0.0625 | AC17: =AI17*AJ17 -> 241875 | AE17: =P17/10^6 -> 0 | AF17: =IF(AL17=0,0,AE17/AL17) -> 0 | AG17: =(AH17*AI17*AJ17)/10^6 -> 39.425625 | AH17: 163 | AI17: 250.12927 | AJ17: 967 | AK17: 800 | AL17: =(AK17*AJ17*AI17)/10^6 -> 193.5 | AM17: =AL17*U17 -> 133.03125 | AN17: =AI17*AK17 -> 200103.41 | AO17: =AH17*AI17 -> 40771.07 | AP17: =U17+AB17 -> 0.75 | AQ17: =AL17*AP17/(AG17+AE17) -> 3.6809816 | AR17: A lançar
A18: MAP055 | B18: A DEFINIR I - MACAE | C18: https://earth.google.com/web/search/MACAE/@-22.36624118,-41.8234272,34.24557963a,6150.26313789d,35y,0h,0t,0r/data=CiwiJgokCcmdsN-e6TbAEVdlXJdI9TbAGUMWAjLoEkXAIbglujnGH0XAQgIIAToDCgEwQgIIAEoICJfn8a8FEAA?authuser=0 | D18: 1 | E18: Estudo de viabilidade | G18: 2642 | J18: 236 | K18: SUDESTE | L18: MACAE | M18: RJ | N18: A DEFINIR | O18: Parceria | P18: 0 | Q18: Loteamento | R18: - | S18: 2029 | T18: 47483 | U18: 0.595855 | V18: 0.35 | W18: =SUM(U18:V18) -> 0.945855 | X18: 0.05 | Y18: 0.09 | Z18: 0.068 | AA18: 0.198 | AB18: 0.054145 | AC18: =AI18*AJ18 -> 183738 | AE18: =P18/10^6 -> 0 | AF18: =IF(AL18=0,0,AE18/AL18) -> 0 | AG18: =(AH18*AI18*AJ18)/10^6 -> 29.949294 | AH18: 163 | AI18: 271 | AJ18: 678 | AK18: 600 | AL18: =(AK18*AJ18*AI18)/10^6 -> 110.2428 | AM18: =AL18*U18 -> 65.688724 | AN18: =AI18*AK18 -> 162600 | AO18: =AH18*AI18 -> 44173 | AP18: =U18+AB18 -> 0.65 | AQ18: =AL18*AP18/(AG18+AE18) -> 2.392638 | AR18: A lançar
